[2021-10-05 12:18:09] I facebo | FB self.domain: m1.ogoro.me
[2021-10-05 12:18:09] I facebo | FB self.aws_nlb: m1-core-nlb-d1a3c13eaba292ca.elb.us-east-1.amazonaws.com
[2021-10-05 12:18:09] I facebo | FB initiated: <core.facebook.FB object at 0x7eff65852650>
[2021-10-05 12:18:32] I dynamo | DYNAMO initiated
[2021-10-05 12:18:34] I engine | RUNNER initiated: <core.engine.Runner object at 0x7f15cdaced90>
[2021-10-05 12:18:34] I engine | RUNNER started: <core.engine.Runner object at 0x7f15cdaced90>
[2021-10-05 12:18:34] I telegr | BOT initiated: <core.telegram.Bot object at 0x7f15cd9f8a90>
[2021-10-05 12:18:34] I engine | RUNNER queue_worker started: 11354
[2021-10-05 12:18:34] I telegr | BOT polling: <core.telegram.Bot object at 0x7f15cd9f8a90>
[2021-10-05 12:18:34] I telegr | BOT enumerate_threads: [<_MainThread(MainThread, started 139732493158208)>, <Thread(QueueManagerThread, started daemon 139731620329216)>, <Thread(Telegram bot polling, started daemon 139731603543808)>, <Thread(QueueFeederThread, initial daemon)>]
[2021-10-05 12:18:34] I cognit | COGNITO self.client_id: 27k0oc5jiv5m28l2ldre8c79f3
[2021-10-05 12:18:34] I cognit | COGNITO self.user_pool_id: us-east-1_Vzc2ve15D
[2021-10-05 12:18:34] I cognit | COGNITO self.domain: m1.ogoro.me
[2021-10-05 12:18:34] I cognit | COGNITO self.aws_nlb: m1-core-nlb-d1a3c13eaba292ca.elb.us-east-1.amazonaws.com
[2021-10-05 12:18:34] I cognit | COGNITO initiated: <core.cognito.Users object at 0x7f15cd98f450>
[2021-10-05 12:18:34] I cognit | COGNITO self.app.cognito: <core.cognito.Users object at 0x7f15cd98f450>
[2021-10-05 12:18:34] I facebo | FB self.domain: m1.ogoro.me
[2021-10-05 12:18:34] I facebo | FB self.aws_nlb: m1-core-nlb-d1a3c13eaba292ca.elb.us-east-1.amazonaws.com
[2021-10-05 12:18:34] I facebo | FB initiated: <core.facebook.FB object at 0x7f15ceb8e190>
[2021-10-05 12:18:44] I engine | Traceback (most recent call last):
  File "/home/ec2-user/environment/m1/app/core-service/core/engine.py", line 127, in wrapper
    return function(self, *args, **kwargs)
  File "/home/ec2-user/environment/m1/app/core-service/core/engine.py", line 159, in queue_worker
    time.sleep(1)
  File "/home/ec2-user/environment/m1/app/core-service/core/app.py", line 66, in termination_handler
    print(f'APP termination_handler signal {signal}, {frame}')
  File "/home/ec2-user/environment/m1/app/core-service/core/app.py", line 66, in termination_handler
    print(f'APP termination_handler signal {signal}, {frame}')
RuntimeError: reentrant call inside <_io.BufferedWriter name='<stdout>'>

[2021-10-05 12:20:58] I dynamo | DYNAMO initiated
[2021-10-05 12:21:00] I engine | RUNNER initiated: <core.engine.Runner object at 0x7fac70b89a90>
[2021-10-05 12:21:00] I engine | RUNNER started: <core.engine.Runner object at 0x7fac70b89a90>
[2021-10-05 12:21:00] I telegr | BOT initiated: <core.telegram.Bot object at 0x7fac70a47050>
[2021-10-05 12:21:00] I engine | RUNNER queue_worker started: 11787
[2021-10-05 12:21:00] I telegr | BOT polling: <core.telegram.Bot object at 0x7fac70a47050>
[2021-10-05 12:21:00] I telegr | BOT enumerate_threads: [<_MainThread(MainThread, started 140379473606464)>, <Thread(QueueManagerThread, started daemon 140378600875776)>, <Thread(Telegram bot polling, started daemon 140378514646784)>, <Thread(QueueFeederThread, initial daemon)>]
[2021-10-05 12:21:00] I cognit | COGNITO initiated: <core.cognito.Users object at 0x7fac80183650>
[2021-10-05 12:21:00] I facebo | FB self.domain: m1.ogoro.me
[2021-10-05 12:21:00] I facebo | FB self.aws_nlb: m1-core-nlb-d1a3c13eaba292ca.elb.us-east-1.amazonaws.com
[2021-10-05 12:21:00] I facebo | FB initiated: <core.facebook.FB object at 0x7fac70a47a90>
[2021-10-05 12:21:12] I cognit | LOGIN token_response: {'ChallengeParameters': {}, 'AuthenticationResult': {'AccessToken': 'eyJraWQiOiJxMzJ3cWpsSUFZXC9wbllVTjlnUkhrNlQxZXBLUzE2c3UxYlpvaGpOR1B4ST0iLCJhbGciOiJSUzI1NiJ9.eyJvcmlnaW5fanRpIjoiZmRiNDFkYjEtMjY5ZS00NmQxLThiNWUtZDE3NzlmOWYxNWZjIiwic3ViIjoiMzg2ZTExOGUtMmVjMy00ZmZjLTkzODUtN2JkODIwNGJmNjRhIiwiZXZlbnRfaWQiOiJkNjkzN2ZlNC04MTM4LTRlYjktOGI1NS1iNjg3OTIwOWM0N2QiLCJ0b2tlbl91c2UiOiJhY2Nlc3MiLCJzY29wZSI6ImF3cy5jb2duaXRvLnNpZ25pbi51c2VyLmFkbWluIiwiYXV0aF90aW1lIjoxNjMzNDM2NDcyLCJpc3MiOiJodHRwczpcL1wvY29nbml0by1pZHAudXMtZWFzdC0xLmFtYXpvbmF3cy5jb21cL3VzLWVhc3QtMV9WemMydmUxNUQiLCJleHAiOjE2MzM0NDAwNzIsImlhdCI6MTYzMzQzNjQ3MiwianRpIjoiZDAzZTBmNGItYTM0NS00NGM4LTk2ODItMGI1NzlmNjJlNTQzIiwiY2xpZW50X2lkIjoiMjdrMG9jNWppdjVtMjhsMmxkcmU4Yzc5ZjMiLCJ1c2VybmFtZSI6InRlc3QyIn0.h4T0bLCzIIT1EW9SB2jUvB1rH9eouGL7vK8TvgfKHWXJIVEiwxeGqw4AIjfvB7SFPIEBLtNsmaNfb1eZpG1DrGxlpmomRsTbDeAHoylil_FbuqEuaN2Ut2pscY8yVzBjza6BO0iLaT-oTEQMHCemWT_Ans-X9wATapOgbCevdQuy6V-Y6qQzhFq6R29kdDHl1eZg7jRxM7ARwQOHaKZqUVKt2Y8-iZGLmdH2ZicEdlc1IatbfZYKu9lA186GlptsKNACw5d6BmF5uVhQTJqUdMPpNiKMH6Abuc59enWxZMWXb_1TuadycU7OooD3DMBiFFuD96QyJQ5ZlVVwkkJ4Mw', 'ExpiresIn': 3600, 'TokenType': 'Bearer', 'RefreshToken': 'eyJjdHkiOiJKV1QiLCJlbmMiOiJBMjU2R0NNIiwiYWxnIjoiUlNBLU9BRVAifQ.rVYo_cfq56w9o8fEX70bPmW8D0QQ4sYB3yRm8hH0MD6bp360Df8y3hZLsfXKK319p70lKUlWbr4aIjGZgZTa66FCok2p3IZZoTn3zZE_pMgz3ryPPhaucfOpB2pgWHMCbHsL5bRHLXMOd-XRa5swvNLCjUtPfEXptWyHR-XJCtkvutpiTusmvA4muJ_FA88SgfrtvrFVR6J7DQQHPF3fKi23bSMAbIMVAyCLXRZ2Bw-q6UzBUqFM4wWAFzVdXrtNBKYqfRO-FPnoWvr3WmTPVnEi2nnyAn_DK9_34Jx3vZzebpmco6tpLop8h4PIzE4fGSV67jepnPUj8QOC9PWUeg._K5O0NSqdA8PaUT3.rwbBGJIOiPmCobFTqGAoeMB6uhsD8vt2WLFL-ZMxuUhjyCzC4ZWZVdULilTDbwLMob2eHdxkPRRvW6TIolzWsUBXDgzbTKO6XpLqlXDUoj6_Mg-sJf9NTKYYZdWPEEb46r5CQkQio-zoNsC8SWEWHUUBtPWixOM36MRkvnnN0X3OAUKQ8WYZmlxSwGHxBl_VVanxgEUUjkE-3f357uON7bW5swSPEEM236sxJEN1ljdoSTYXzs2WmudKdmUBYDnD9PW9ZkBuabTTET_teFGtRyK7Wqm577TEXwXy5uM2gt4m28zya3kEdzJa67gjHPM8Zn3RZm1UE0c-nx7Fslfy9FV3K-0x9gIQaJDzXWuY4mPMXaY7kDQjWKT7YyAU2tys1edNg9CoL5NDNRoHKOkwerNu-gKVOuiohLLOdBMgDDGmwoS4prVIfeobD89gzvSqo_wq-bN2ObiHwa8R64w_ItnSI7JjIc2wFcZPc7IpP3wZ77VZvtwkmWj9LWUMliALGgVPhzK5WJrDpDVmBXBmAJQOKund8BPFHg_CC2ghMsyNIgXVZaQZRhT6XqEf8onMH2urxfZ5lSdftbAQYoHxDkCxzgw4wkzMKVfDiHdMfl7rJN6BnyRjZy8rHsmGwdzT8XJd3d4KwBWf8TR5W-ypK6Mkvd0qumMhOf7r3flWLfvnxhM4zqwo8Bj7STpgjmxnCI2cAQQcYLDWZK__XRBDixI6IlbvqOiZzUSRBfeLB0iMHO4gU0ePrkNeHVijXF9PBEzISx-VsMXp6ekmDDffy838BeeqwhDY0PTBrGhHAD7-64QxMKYG0lxufwztorWX5bYwD_tB-JwmC4S7eYJ8PH4y8N1UQJZ9gD09GqC_ckVgJ6xSWD55-aHAyHCe4EeC74adtkNijaMgOSa2BiCkFL5pS_7BePwkppdp4LVlvD7Bys6tdGuoXffifgeAo9rnOACGgRmrUFGibLU2nqFW7UAOYKT9cZ3zX2gahKpwFTQA2dQpzmVs6sZFk38W6ax3tcyosy1Mk5h1-x9YCqBED_fn22Iasf8I6JNzSBkWSK2SbDOuyBQ13zw2W-gt_l2KXl8aHhtwP7LsnnAuGUVFjTVNd2YH0jl80xfqRxPX5KFZbJWx9O5lkCJ2O21KpXXxjsPIh_K7s1QSCQ72_tm2z5dXgZ_UWkWxgSwr6y1XlG4PJbd7kLMKpWEPrC-vi8P0XCbez5t3p6fOo93eS0UQVaBVpGZej_uzRJUZET8Q0fdENE6_tdCuiKUu8mAs15VySKU.LYXu5XCbOm5lURu4cOhrAg', 'IdToken': 'eyJraWQiOiI1eENGYWNhVmx5TXE4NU14SkdqYTdtdXFpQndRbWFQU3hLYVNmcXlPekZvPSIsImFsZyI6IlJTMjU2In0.eyJvcmlnaW5fanRpIjoiZmRiNDFkYjEtMjY5ZS00NmQxLThiNWUtZDE3NzlmOWYxNWZjIiwic3ViIjoiMzg2ZTExOGUtMmVjMy00ZmZjLTkzODUtN2JkODIwNGJmNjRhIiwiYXVkIjoiMjdrMG9jNWppdjVtMjhsMmxkcmU4Yzc5ZjMiLCJldmVudF9pZCI6ImQ2OTM3ZmU0LTgxMzgtNGViOS04YjU1LWI2ODc5MjA5YzQ3ZCIsInRva2VuX3VzZSI6ImlkIiwiYXV0aF90aW1lIjoxNjMzNDM2NDcyLCJpc3MiOiJodHRwczpcL1wvY29nbml0by1pZHAudXMtZWFzdC0xLmFtYXpvbmF3cy5jb21cL3VzLWVhc3QtMV9WemMydmUxNUQiLCJjb2duaXRvOnVzZXJuYW1lIjoidGVzdDIiLCJleHAiOjE2MzM0NDAwNzIsImlhdCI6MTYzMzQzNjQ3MiwianRpIjoiODNkMjNiODMtNmRjMi00ZDNiLTg0YmEtZDg2NWY5MTQ2MjI2In0.Dq6UfET8NnDgwbQOmYs9nCJWEtCREerDUUDTpwU6w7BiHP2R2Se_COdrc8zFfacLK566IIm5wa62OP62NrPPpopUFy8gubHYPElB9WArj5bPlmsuZ6g01UpHa7uSvWMWCPjjsElnrt4t5_oQ8vFA-3D0zE7N5YPV9X3fWmLNyNPm1lFucaBAUjmJww7F9TDGWY_NlimEIvQoUNTULkItOiGxsmgkmEpCEZEm5P6tTdO4MvnrD3W5zvrWFO9EBJSzy7xnlS5663DsvU5Twu2xMdsxqXiaUhge2E2ANcollMfKP3INkmS-1ONUwFOs93VRRwDVHNQQ0yc4ugHEm7WixQ'}, 'ResponseMetadata': {'RequestId': 'd6937fe4-8138-4eb9-8b55-b6879209c47d', 'HTTPStatusCode': 200, 'HTTPHeaders': {'date': 'Tue, 05 Oct 2021 12:21:12 GMT', 'content-type': 'application/x-amz-json-1.1', 'content-length': '3871', 'connection': 'keep-alive', 'x-amzn-requestid': 'd6937fe4-8138-4eb9-8b55-b6879209c47d'}, 'RetryAttempts': 0}}
[2021-10-05 12:21:12] I cognit | LOGIN access_token: eyJraWQiOiJxMzJ3cWpsSUFZXC9wbllVTjlnUkhrNlQxZXBLUzE2c3UxYlpvaGpOR1B4ST0iLCJhbGciOiJSUzI1NiJ9.eyJvcmlnaW5fanRpIjoiZmRiNDFkYjEtMjY5ZS00NmQxLThiNWUtZDE3NzlmOWYxNWZjIiwic3ViIjoiMzg2ZTExOGUtMmVjMy00ZmZjLTkzODUtN2JkODIwNGJmNjRhIiwiZXZlbnRfaWQiOiJkNjkzN2ZlNC04MTM4LTRlYjktOGI1NS1iNjg3OTIwOWM0N2QiLCJ0b2tlbl91c2UiOiJhY2Nlc3MiLCJzY29wZSI6ImF3cy5jb2duaXRvLnNpZ25pbi51c2VyLmFkbWluIiwiYXV0aF90aW1lIjoxNjMzNDM2NDcyLCJpc3MiOiJodHRwczpcL1wvY29nbml0by1pZHAudXMtZWFzdC0xLmFtYXpvbmF3cy5jb21cL3VzLWVhc3QtMV9WemMydmUxNUQiLCJleHAiOjE2MzM0NDAwNzIsImlhdCI6MTYzMzQzNjQ3MiwianRpIjoiZDAzZTBmNGItYTM0NS00NGM4LTk2ODItMGI1NzlmNjJlNTQzIiwiY2xpZW50X2lkIjoiMjdrMG9jNWppdjVtMjhsMmxkcmU4Yzc5ZjMiLCJ1c2VybmFtZSI6InRlc3QyIn0.h4T0bLCzIIT1EW9SB2jUvB1rH9eouGL7vK8TvgfKHWXJIVEiwxeGqw4AIjfvB7SFPIEBLtNsmaNfb1eZpG1DrGxlpmomRsTbDeAHoylil_FbuqEuaN2Ut2pscY8yVzBjza6BO0iLaT-oTEQMHCemWT_Ans-X9wATapOgbCevdQuy6V-Y6qQzhFq6R29kdDHl1eZg7jRxM7ARwQOHaKZqUVKt2Y8-iZGLmdH2ZicEdlc1IatbfZYKu9lA186GlptsKNACw5d6BmF5uVhQTJqUdMPpNiKMH6Abuc59enWxZMWXb_1TuadycU7OooD3DMBiFFuD96QyJQ5ZlVVwkkJ4Mw
[2021-10-05 12:21:12] I cognit | LOGIN refresh_token: eyJjdHkiOiJKV1QiLCJlbmMiOiJBMjU2R0NNIiwiYWxnIjoiUlNBLU9BRVAifQ.rVYo_cfq56w9o8fEX70bPmW8D0QQ4sYB3yRm8hH0MD6bp360Df8y3hZLsfXKK319p70lKUlWbr4aIjGZgZTa66FCok2p3IZZoTn3zZE_pMgz3ryPPhaucfOpB2pgWHMCbHsL5bRHLXMOd-XRa5swvNLCjUtPfEXptWyHR-XJCtkvutpiTusmvA4muJ_FA88SgfrtvrFVR6J7DQQHPF3fKi23bSMAbIMVAyCLXRZ2Bw-q6UzBUqFM4wWAFzVdXrtNBKYqfRO-FPnoWvr3WmTPVnEi2nnyAn_DK9_34Jx3vZzebpmco6tpLop8h4PIzE4fGSV67jepnPUj8QOC9PWUeg._K5O0NSqdA8PaUT3.rwbBGJIOiPmCobFTqGAoeMB6uhsD8vt2WLFL-ZMxuUhjyCzC4ZWZVdULilTDbwLMob2eHdxkPRRvW6TIolzWsUBXDgzbTKO6XpLqlXDUoj6_Mg-sJf9NTKYYZdWPEEb46r5CQkQio-zoNsC8SWEWHUUBtPWixOM36MRkvnnN0X3OAUKQ8WYZmlxSwGHxBl_VVanxgEUUjkE-3f357uON7bW5swSPEEM236sxJEN1ljdoSTYXzs2WmudKdmUBYDnD9PW9ZkBuabTTET_teFGtRyK7Wqm577TEXwXy5uM2gt4m28zya3kEdzJa67gjHPM8Zn3RZm1UE0c-nx7Fslfy9FV3K-0x9gIQaJDzXWuY4mPMXaY7kDQjWKT7YyAU2tys1edNg9CoL5NDNRoHKOkwerNu-gKVOuiohLLOdBMgDDGmwoS4prVIfeobD89gzvSqo_wq-bN2ObiHwa8R64w_ItnSI7JjIc2wFcZPc7IpP3wZ77VZvtwkmWj9LWUMliALGgVPhzK5WJrDpDVmBXBmAJQOKund8BPFHg_CC2ghMsyNIgXVZaQZRhT6XqEf8onMH2urxfZ5lSdftbAQYoHxDkCxzgw4wkzMKVfDiHdMfl7rJN6BnyRjZy8rHsmGwdzT8XJd3d4KwBWf8TR5W-ypK6Mkvd0qumMhOf7r3flWLfvnxhM4zqwo8Bj7STpgjmxnCI2cAQQcYLDWZK__XRBDixI6IlbvqOiZzUSRBfeLB0iMHO4gU0ePrkNeHVijXF9PBEzISx-VsMXp6ekmDDffy838BeeqwhDY0PTBrGhHAD7-64QxMKYG0lxufwztorWX5bYwD_tB-JwmC4S7eYJ8PH4y8N1UQJZ9gD09GqC_ckVgJ6xSWD55-aHAyHCe4EeC74adtkNijaMgOSa2BiCkFL5pS_7BePwkppdp4LVlvD7Bys6tdGuoXffifgeAo9rnOACGgRmrUFGibLU2nqFW7UAOYKT9cZ3zX2gahKpwFTQA2dQpzmVs6sZFk38W6ax3tcyosy1Mk5h1-x9YCqBED_fn22Iasf8I6JNzSBkWSK2SbDOuyBQ13zw2W-gt_l2KXl8aHhtwP7LsnnAuGUVFjTVNd2YH0jl80xfqRxPX5KFZbJWx9O5lkCJ2O21KpXXxjsPIh_K7s1QSCQ72_tm2z5dXgZ_UWkWxgSwr6y1XlG4PJbd7kLMKpWEPrC-vi8P0XCbez5t3p6fOo93eS0UQVaBVpGZej_uzRJUZET8Q0fdENE6_tdCuiKUu8mAs15VySKU.LYXu5XCbOm5lURu4cOhrAg
[2021-10-05 12:21:12] I cognit | LOGIN user_response: {'Username': 'test2', 'UserAttributes': [{'Name': 'sub', 'Value': '386e118e-2ec3-4ffc-9385-7bd8204bf64a'}], 'ResponseMetadata': {'RequestId': 'bb3c6d83-469d-4f76-b8b5-7c4cd571bdb3', 'HTTPStatusCode': 200, 'HTTPHeaders': {'date': 'Tue, 05 Oct 2021 12:21:12 GMT', 'content-type': 'application/x-amz-json-1.1', 'content-length': '101', 'connection': 'keep-alive', 'x-amzn-requestid': 'bb3c6d83-469d-4f76-b8b5-7c4cd571bdb3'}, 'RetryAttempts': 0}}
[2021-10-05 12:21:12] I cognit | LOGIN user_attributes: [{'Name': 'sub', 'Value': '386e118e-2ec3-4ffc-9385-7bd8204bf64a'}]
[2021-10-05 12:21:12] I cognit | LOGIN user_sub: 386e118e-2ec3-4ffc-9385-7bd8204bf64a
[2021-10-05 12:26:40] I engine | Traceback (most recent call last):
  File "/home/ec2-user/environment/m1/app/core-service/core/engine.py", line 127, in wrapper
    return function(self, *args, **kwargs)
  File "/home/ec2-user/environment/m1/app/core-service/core/engine.py", line 159, in queue_worker
    time.sleep(1)
  File "/home/ec2-user/environment/m1/app/core-service/core/app.py", line 66, in termination_handler
    print(f'APP termination_handler signal {signal}, {frame}')
  File "/home/ec2-user/environment/m1/app/core-service/core/app.py", line 66, in termination_handler
    print(f'APP termination_handler signal {signal}, {frame}')
RuntimeError: reentrant call inside <_io.BufferedWriter name='<stdout>'>

[2021-10-05 12:26:45] I dynamo | DYNAMO initiated
[2021-10-05 12:26:47] I engine | RUNNER initiated: <core.engine.Runner object at 0x7f8d0bc4b3d0>
[2021-10-05 12:26:47] I engine | RUNNER queue_worker started: 12409
[2021-10-05 12:26:47] I engine | RUNNER started: <core.engine.Runner object at 0x7f8d0bc4b3d0>
[2021-10-05 12:26:47] I telegr | BOT initiated: <core.telegram.Bot object at 0x7f8d0b798d50>
[2021-10-05 12:26:47] I telegr | BOT polling: <core.telegram.Bot object at 0x7f8d0b798d50>
[2021-10-05 12:26:47] I telegr | BOT enumerate_threads: [<_MainThread(MainThread, started 140244631889728)>, <Thread(QueueManagerThread, started daemon 140243759134464)>, <Thread(Telegram bot polling, started daemon 140243742349056)>, <Thread(QueueFeederThread, initial daemon)>]
[2021-10-05 12:26:47] I cognit | COGNITO initiated: <core.cognito.Users object at 0x7f8d0b72e710>
[2021-10-05 12:26:47] I facebo | FB self.domain: m1.ogoro.me
[2021-10-05 12:26:47] I facebo | FB self.aws_nlb: m1-core-nlb-d1a3c13eaba292ca.elb.us-east-1.amazonaws.com
[2021-10-05 12:26:47] I facebo | FB initiated: <core.facebook.FB object at 0x7f8d0b72e750>
[2021-10-05 12:36:15] I engine | Traceback (most recent call last):
  File "/home/ec2-user/environment/m1/app/core-service/core/engine.py", line 127, in wrapper
    return function(self, *args, **kwargs)
  File "/home/ec2-user/environment/m1/app/core-service/core/engine.py", line 159, in queue_worker
    time.sleep(1)
  File "/home/ec2-user/environment/m1/app/core-service/core/app.py", line 66, in termination_handler
    print(f'APP termination_handler signal {signal}, {frame}')
OSError: [Errno 5] Input/output error

[2021-10-05 12:36:20] I dynamo | DYNAMO initiated
[2021-10-05 12:36:23] I engine | RUNNER initiated: <core.engine.Runner object at 0x7fe38ffc9290>
[2021-10-05 12:36:23] I engine | RUNNER started: <core.engine.Runner object at 0x7fe38ffc9290>
[2021-10-05 12:36:23] I telegr | BOT initiated: <core.telegram.Bot object at 0x7fe38ee32810>
[2021-10-05 12:36:23] I engine | RUNNER queue_worker started: 13304
[2021-10-05 12:36:23] I telegr | BOT polling: <core.telegram.Bot object at 0x7fe38ee32810>
[2021-10-05 12:36:23] I telegr | BOT enumerate_threads: [<_MainThread(MainThread, started 140616203888448)>, <Thread(QueueManagerThread, started daemon 140615331059456)>, <Thread(Telegram bot polling, started daemon 140615314274048)>, <Thread(QueueFeederThread, initial daemon)>]
[2021-10-05 12:36:23] I cognit | COGNITO initiated: <core.cognito.Users object at 0x7fe38edc9190>
[2021-10-05 12:36:23] I facebo | FB self.domain: m1.ogoro.me
[2021-10-05 12:36:23] I facebo | FB self.aws_nlb: m1-core-nlb-d1a3c13eaba292ca.elb.us-east-1.amazonaws.com
[2021-10-05 12:36:23] I facebo | FB initiated: <core.facebook.FB object at 0x7fe38edc91d0>
[2021-10-05 12:36:26] I engine | Traceback (most recent call last):
  File "/home/ec2-user/environment/m1/app/core-service/core/engine.py", line 127, in wrapper
    return function(self, *args, **kwargs)
  File "/home/ec2-user/environment/m1/app/core-service/core/engine.py", line 159, in queue_worker
    time.sleep(1)
  File "/home/ec2-user/environment/m1/app/core-service/core/app.py", line 66, in termination_handler
    print(f'APP termination_handler signal {signal}, {frame}')
  File "/home/ec2-user/environment/m1/app/core-service/core/app.py", line 66, in termination_handler
    print(f'APP termination_handler signal {signal}, {frame}')
RuntimeError: reentrant call inside <_io.BufferedWriter name='<stdout>'>

[2021-10-05 12:37:11] I dynamo | DYNAMO initiated
[2021-10-05 12:37:13] I engine | RUNNER initiated: <core.engine.Runner object at 0x7f074acdce90>
[2021-10-05 12:37:13] I engine | RUNNER started: <core.engine.Runner object at 0x7f074acdce90>
[2021-10-05 12:37:13] I telegr | BOT initiated: <core.telegram.Bot object at 0x7f074ac07a50>
[2021-10-05 12:37:13] I engine | RUNNER queue_worker started: 13647
[2021-10-05 12:37:13] I telegr | BOT polling: <core.telegram.Bot object at 0x7f074ac07a50>
[2021-10-05 12:37:13] I telegr | BOT enumerate_threads: [<_MainThread(MainThread, started 139670167881536)>, <Thread(QueueManagerThread, started daemon 139669295126272)>, <Thread(Telegram bot polling, started daemon 139669278340864)>, <Thread(QueueFeederThread, initial daemon)>]
[2021-10-05 12:37:13] I cognit | COGNITO initiated: <core.cognito.Users object at 0x7f074aecc950>
[2021-10-05 12:37:13] I facebo | FB initiated: <core.facebook.FB object at 0x7f074b95b250>
[2021-10-05 12:38:25] I engine | Traceback (most recent call last):
  File "/home/ec2-user/environment/m1/app/core-service/core/engine.py", line 127, in wrapper
    return function(self, *args, **kwargs)
  File "/home/ec2-user/environment/m1/app/core-service/core/engine.py", line 159, in queue_worker
    time.sleep(1)
  File "/home/ec2-user/environment/m1/app/core-service/core/app.py", line 66, in termination_handler
    print(f'APP termination_handler signal {signal}, {frame}')
  File "/home/ec2-user/environment/m1/app/core-service/core/app.py", line 66, in termination_handler
    print(f'APP termination_handler signal {signal}, {frame}')
RuntimeError: reentrant call inside <_io.BufferedWriter name='<stdout>'>

[2021-10-05 12:38:29] I dynamo | DYNAMO initiated
[2021-10-05 12:38:32] I engine | RUNNER initiated: <core.engine.Runner object at 0x7fe456b616d0>
[2021-10-05 12:38:32] I engine | RUNNER queue_worker started: 13989
[2021-10-05 12:38:32] I engine | RUNNER started: <core.engine.Runner object at 0x7fe456b616d0>
[2021-10-05 12:38:32] I telegr | BOT initiated: <core.telegram.Bot object at 0x7fe455c41a50>
[2021-10-05 12:38:32] I telegr | BOT polling: <core.telegram.Bot object at 0x7fe455c41a50>
[2021-10-05 12:38:32] I telegr | BOT enumerate_threads: [<_MainThread(MainThread, started 140619540518720)>, <Thread(QueueManagerThread, started daemon 140618667689728)>, <Thread(Telegram bot polling, started daemon 140618650904320)>, <Thread(QueueFeederThread, initial daemon)>]
[2021-10-05 12:38:32] I cognit | COGNITO initiated: <core.cognito.Users object at 0x7fe455bd7390>
[2021-10-05 12:38:32] I facebo | FB initiated: <core.facebook.FB object at 0x7fe455bd73d0>
[2021-10-05 12:38:54] I facebo | AUTH autorization_url: https://www.facebook.com/v8.0/dialog/oauth?client_id=4137122913076044&redirect_uri=https%3A%2F%2F237bcfb1223a4e479432e7d62a7c73b6.vfs.cloud9.us-east-1.amazonaws.com%2Flogin&scope=public_profile%2Cemail
[2021-10-05 12:39:41] I engine | Traceback (most recent call last):
  File "/home/ec2-user/environment/m1/app/core-service/core/engine.py", line 127, in wrapper
    return function(self, *args, **kwargs)
  File "/home/ec2-user/environment/m1/app/core-service/core/engine.py", line 159, in queue_worker
    time.sleep(1)
  File "/home/ec2-user/environment/m1/app/core-service/core/app.py", line 66, in termination_handler
    print(f'APP termination_handler signal {signal}, {frame}')
  File "/home/ec2-user/environment/m1/app/core-service/core/app.py", line 66, in termination_handler
    print(f'APP termination_handler signal {signal}, {frame}')
RuntimeError: reentrant call inside <_io.BufferedWriter name='<stdout>'>

[2021-10-05 12:39:46] I dynamo | DYNAMO initiated
[2021-10-05 12:39:48] I engine | RUNNER initiated: <core.engine.Runner object at 0x7f59348b2310>
[2021-10-05 12:39:48] I engine | RUNNER queue_worker started: 14341
[2021-10-05 12:39:48] I engine | RUNNER started: <core.engine.Runner object at 0x7f59348b2310>
[2021-10-05 12:39:48] I telegr | BOT initiated: <core.telegram.Bot object at 0x7f59347b6bd0>
[2021-10-05 12:39:48] I telegr | BOT polling: <core.telegram.Bot object at 0x7f59347b6bd0>
[2021-10-05 12:39:48] I telegr | BOT enumerate_threads: [<_MainThread(MainThread, started 140021981583168)>, <Thread(QueueManagerThread, started daemon 140021108827904)>, <Thread(Telegram bot polling, started daemon 140021092042496)>, <Thread(QueueFeederThread, initial daemon)>]
[2021-10-05 12:39:48] I cognit | COGNITO initiated: <core.cognito.Users object at 0x7f593474d590>
[2021-10-05 12:39:48] I facebo | FB initiated: <core.facebook.FB object at 0x7f5935500350>
[2021-10-05 12:39:59] I facebo | AUTH autorization_url: https://www.facebook.com/v8.0/dialog/oauth?client_id=4137122913076044&redirect_uri=https%3A%2F%2F237bcfb1223a4e479432e7d62a7c73b6.vfs.cloud9.us-east-1.amazonaws.com%2Flogin&scope=public_profile%2Cemail
[2021-10-05 12:40:00] I facebo | AUTH code: AQDKe6zsqh1SVb_Rln0KC3rd4eu7JQb4nw3Kda1qbHwEdrFkMwfd_CZKbnejtrLnjG3XLUOqQn385OZgSSKgRunT5ldAVjQ6ydzut6_agKvE5vMMxu_-_J-gJDXkEZcYOa8T5Dddb2dIJ3NuQQIqSlIYs4EQDWYNDZ4THCt780Dvxm7NtE9bbvEQiW-zWuAhTYlmdnKvZgKU-zFDrKbdKiff5GS_FjdXlAc0hbBHtc-PT-JFtZYyi4RwPHEnYZfh7gxsvd0HQYw-JYC7YjwgA2dJ-4Jd6gxqmDorJP1nt7YoHN2P7BPu3K3dZXoYf_FvFj8Gi-qfNhj9JvuHgjUcWghagykvPsqbfmBivHVv8mP42hbX6lsZWYC3wAUkR4_Cxxk
[2021-10-05 12:40:00] I facebo | TOKEN self.redirect_uri_after_proxy: https://237bcfb1223a4e479432e7d62a7c73b6.vfs.cloud9.us-east-1.amazonaws.com/login
[2021-10-05 12:40:00] I facebo | TOKEN parameters: {'client_id': '4137122913076044', 'client_secret': 'c74cd2f60908829da40cee598a9ea7de', 'grant_type': 'authorization_code', 'redirect_uri': 'https://237bcfb1223a4e479432e7d62a7c73b6.vfs.cloud9.us-east-1.amazonaws.com/login', 'code': 'AQDKe6zsqh1SVb_Rln0KC3rd4eu7JQb4nw3Kda1qbHwEdrFkMwfd_CZKbnejtrLnjG3XLUOqQn385OZgSSKgRunT5ldAVjQ6ydzut6_agKvE5vMMxu_-_J-gJDXkEZcYOa8T5Dddb2dIJ3NuQQIqSlIYs4EQDWYNDZ4THCt780Dvxm7NtE9bbvEQiW-zWuAhTYlmdnKvZgKU-zFDrKbdKiff5GS_FjdXlAc0hbBHtc-PT-JFtZYyi4RwPHEnYZfh7gxsvd0HQYw-JYC7YjwgA2dJ-4Jd6gxqmDorJP1nt7YoHN2P7BPu3K3dZXoYf_FvFj8Gi-qfNhj9JvuHgjUcWghagykvPsqbfmBivHVv8mP42hbX6lsZWYC3wAUkR4_Cxxk'}
[2021-10-05 12:40:00] I facebo | TOKEN access_token_url: https://graph.facebook.com/oauth/access_token?client_id=4137122913076044&client_secret=c74cd2f60908829da40cee598a9ea7de&grant_type=authorization_code&redirect_uri=https%3A%2F%2F237bcfb1223a4e479432e7d62a7c73b6.vfs.cloud9.us-east-1.amazonaws.com%2Flogin&code=AQDKe6zsqh1SVb_Rln0KC3rd4eu7JQb4nw3Kda1qbHwEdrFkMwfd_CZKbnejtrLnjG3XLUOqQn385OZgSSKgRunT5ldAVjQ6ydzut6_agKvE5vMMxu_-_J-gJDXkEZcYOa8T5Dddb2dIJ3NuQQIqSlIYs4EQDWYNDZ4THCt780Dvxm7NtE9bbvEQiW-zWuAhTYlmdnKvZgKU-zFDrKbdKiff5GS_FjdXlAc0hbBHtc-PT-JFtZYyi4RwPHEnYZfh7gxsvd0HQYw-JYC7YjwgA2dJ-4Jd6gxqmDorJP1nt7YoHN2P7BPu3K3dZXoYf_FvFj8Gi-qfNhj9JvuHgjUcWghagykvPsqbfmBivHVv8mP42hbX6lsZWYC3wAUkR4_Cxxk
[2021-10-05 12:40:00] I facebo | TOKEN token_response: <Response [200]>
[2021-10-05 12:40:00] I facebo | TOKEN token_response_json: {'access_token': 'EAA6ysP2gQ0wBAErqBouFL5R2lr1xV9tOy1IZA4qcbLP7uYXWykIPTZAMknehzNlwXrDqTw012Et8errnqu18Fe8aR8kGCnmozdFBXIMY2UImZAZB8axMzpz7ZCFphCHqdhRrXpWzyOOXnvZCQhNozbcXUX36hZC6LSkXy77NZB5sThXHK0m5O4idhh5DZAvpBCwowNLTNkJfemCVEB6SQ9reCxBpGcC0HXZCfRUzcniQbu2wZDZD', 'token_type': 'bearer', 'expires_in': 5183935}
[2021-10-05 12:40:00] I facebo | TOKEN facebook_token: EAA6ysP2gQ0wBAErqBouFL5R2lr1xV9tOy1IZA4qcbLP7uYXWykIPTZAMknehzNlwXrDqTw012Et8errnqu18Fe8aR8kGCnmozdFBXIMY2UImZAZB8axMzpz7ZCFphCHqdhRrXpWzyOOXnvZCQhNozbcXUX36hZC6LSkXy77NZB5sThXHK0m5O4idhh5DZAvpBCwowNLTNkJfemCVEB6SQ9reCxBpGcC0HXZCfRUzcniQbu2wZDZD
[2021-10-05 12:40:00] I facebo | CLAIMS me_endpoint: https://graph.facebook.com/me
[2021-10-05 12:40:00] I facebo | CLAIMS parameters: {'fields': 'name,email,picture,short_name', 'access_token': 'EAA6ysP2gQ0wBAErqBouFL5R2lr1xV9tOy1IZA4qcbLP7uYXWykIPTZAMknehzNlwXrDqTw012Et8errnqu18Fe8aR8kGCnmozdFBXIMY2UImZAZB8axMzpz7ZCFphCHqdhRrXpWzyOOXnvZCQhNozbcXUX36hZC6LSkXy77NZB5sThXHK0m5O4idhh5DZAvpBCwowNLTNkJfemCVEB6SQ9reCxBpGcC0HXZCfRUzcniQbu2wZDZD'}
[2021-10-05 12:40:00] I facebo | CLAIMS me_response_json: {'name': 'Mykhailo Ogorodnikov', 'email': 'mi.ogoro@gmail.com', 'picture': {'data': {'height': 50, 'is_silhouette': False, 'url': 'https://platform-lookaside.fbsbx.com/platform/profilepic/?asid=4052844671451235&height=50&width=50&ext=1636029600&hash=AeSofvmpKKS_vSjRhfo', 'width': 50}}, 'short_name': 'Mykhailo', 'id': '4052844671451235'}
[2021-10-05 12:40:00] E    app | Exception on /login [GET]
Traceback (most recent call last):
  File "/home/ec2-user/environment/flask-env/lib64/python3.7/site-packages/flask/app.py", line 2070, in wsgi_app
    response = self.full_dispatch_request()
  File "/home/ec2-user/environment/flask-env/lib64/python3.7/site-packages/flask/app.py", line 1515, in full_dispatch_request
    rv = self.handle_user_exception(e)
  File "/home/ec2-user/environment/flask-env/lib64/python3.7/site-packages/flask_cors/extension.py", line 165, in wrapped_function
    return cors_after_request(app.make_response(f(*args, **kwargs)))
  File "/home/ec2-user/environment/flask-env/lib64/python3.7/site-packages/flask/app.py", line 1513, in full_dispatch_request
    rv = self.dispatch_request()
  File "/home/ec2-user/environment/flask-env/lib64/python3.7/site-packages/flask/app.py", line 1499, in dispatch_request
    return self.ensure_sync(self.view_functions[rule.endpoint])(**req.view_args)
  File "/home/ec2-user/environment/m1/app/core-service/core/routes.py", line 46, in login
    redirect_url = facebook.login_facebook_user(facebook_token)
  File "/home/ec2-user/environment/m1/app/core-service/core/facebook.py", line 118, in login_facebook_user
    self.users.populate_facebook_user()
AttributeError: 'NoneType' object has no attribute 'populate_facebook_user'
[2021-10-05 12:41:35] I engine | Traceback (most recent call last):
  File "/home/ec2-user/environment/m1/app/core-service/core/engine.py", line 127, in wrapper
    return function(self, *args, **kwargs)
  File "/home/ec2-user/environment/m1/app/core-service/core/engine.py", line 159, in queue_worker
    time.sleep(1)
  File "/home/ec2-user/environment/m1/app/core-service/core/app.py", line 66, in termination_handler
    print(f'APP termination_handler signal {signal}, {frame}')
  File "/home/ec2-user/environment/m1/app/core-service/core/app.py", line 66, in termination_handler
    print(f'APP termination_handler signal {signal}, {frame}')
RuntimeError: reentrant call inside <_io.BufferedWriter name='<stdout>'>

[2021-10-05 12:41:40] I dynamo | DYNAMO initiated
[2021-10-05 12:41:42] I engine | RUNNER initiated: <core.engine.Runner object at 0x7fb180916190>
[2021-10-05 12:41:42] I engine | RUNNER started: <core.engine.Runner object at 0x7fb180916190>
[2021-10-05 12:41:42] I telegr | BOT initiated: <core.telegram.Bot object at 0x7fb18028e910>
[2021-10-05 12:41:42] I engine | RUNNER queue_worker started: 14757
[2021-10-05 12:41:42] I telegr | BOT polling: <core.telegram.Bot object at 0x7fb18028e910>
[2021-10-05 12:41:42] I telegr | BOT enumerate_threads: [<_MainThread(MainThread, started 140401208432448)>, <Thread(QueueManagerThread, started daemon 140400335603456)>, <Thread(Telegram bot polling, started daemon 140400318818048)>, <Thread(QueueFeederThread, initial daemon)>]
[2021-10-05 12:41:42] I cognit | COGNITO initiated: <core.cognito.Users object at 0x7fb1802232d0>
[2021-10-05 12:41:42] I facebo | FB initiated: <core.facebook.FB object at 0x7fb180223310>
[2021-10-05 12:41:53] I facebo | AUTH autorization_url: https://www.facebook.com/v8.0/dialog/oauth?client_id=4137122913076044&redirect_uri=https%3A%2F%2F237bcfb1223a4e479432e7d62a7c73b6.vfs.cloud9.us-east-1.amazonaws.com%2Flogin&scope=public_profile%2Cemail
[2021-10-05 12:41:54] I facebo | AUTH code: AQBW3LiwJR5_cLLl_TRtilJTyO7WlisMJKmP1ifZG8QI0cT9a-K5vhRslx_MLVBLH9ppFs_LxHrO-lgCG0zo6vexwildbnWC9CcZbdpSQ6K1gU00dFjOzIDh6Q-8HTgl2Eq8maM00Lcxmb7KJcqNO2y6oNzFZ5oW3wLe6GoyJ0FbFhLNzPNCYcmoZBirDgQOvSC-_Xb-ixoxTP6tLai4-k3BcfEINrXaiUk_Ph9BIU7A6eVh8x-iTZTCNYt4dm-lC24IglxNgY4AAniggEb7D8xJTwjgC086AYdbga-DZ-VoJquAYG3RfoL6RtddO1r_WWNLLv2PjOoBzoGyvtG8R2YITd5QW1_hOe1928Mstg1yZanoYftHGNvcZsu9Mv6giko
[2021-10-05 12:41:54] I facebo | TOKEN self.redirect_uri_after_proxy: https://237bcfb1223a4e479432e7d62a7c73b6.vfs.cloud9.us-east-1.amazonaws.com/login
[2021-10-05 12:41:54] I facebo | TOKEN parameters: {'client_id': '4137122913076044', 'client_secret': 'c74cd2f60908829da40cee598a9ea7de', 'grant_type': 'authorization_code', 'redirect_uri': 'https://237bcfb1223a4e479432e7d62a7c73b6.vfs.cloud9.us-east-1.amazonaws.com/login', 'code': 'AQBW3LiwJR5_cLLl_TRtilJTyO7WlisMJKmP1ifZG8QI0cT9a-K5vhRslx_MLVBLH9ppFs_LxHrO-lgCG0zo6vexwildbnWC9CcZbdpSQ6K1gU00dFjOzIDh6Q-8HTgl2Eq8maM00Lcxmb7KJcqNO2y6oNzFZ5oW3wLe6GoyJ0FbFhLNzPNCYcmoZBirDgQOvSC-_Xb-ixoxTP6tLai4-k3BcfEINrXaiUk_Ph9BIU7A6eVh8x-iTZTCNYt4dm-lC24IglxNgY4AAniggEb7D8xJTwjgC086AYdbga-DZ-VoJquAYG3RfoL6RtddO1r_WWNLLv2PjOoBzoGyvtG8R2YITd5QW1_hOe1928Mstg1yZanoYftHGNvcZsu9Mv6giko'}
[2021-10-05 12:41:54] I facebo | TOKEN access_token_url: https://graph.facebook.com/oauth/access_token?client_id=4137122913076044&client_secret=c74cd2f60908829da40cee598a9ea7de&grant_type=authorization_code&redirect_uri=https%3A%2F%2F237bcfb1223a4e479432e7d62a7c73b6.vfs.cloud9.us-east-1.amazonaws.com%2Flogin&code=AQBW3LiwJR5_cLLl_TRtilJTyO7WlisMJKmP1ifZG8QI0cT9a-K5vhRslx_MLVBLH9ppFs_LxHrO-lgCG0zo6vexwildbnWC9CcZbdpSQ6K1gU00dFjOzIDh6Q-8HTgl2Eq8maM00Lcxmb7KJcqNO2y6oNzFZ5oW3wLe6GoyJ0FbFhLNzPNCYcmoZBirDgQOvSC-_Xb-ixoxTP6tLai4-k3BcfEINrXaiUk_Ph9BIU7A6eVh8x-iTZTCNYt4dm-lC24IglxNgY4AAniggEb7D8xJTwjgC086AYdbga-DZ-VoJquAYG3RfoL6RtddO1r_WWNLLv2PjOoBzoGyvtG8R2YITd5QW1_hOe1928Mstg1yZanoYftHGNvcZsu9Mv6giko
[2021-10-05 12:41:54] I facebo | TOKEN token_response: <Response [200]>
[2021-10-05 12:41:54] I facebo | TOKEN token_response_json: {'access_token': 'EAA6ysP2gQ0wBABp47teEdVs6HzvyNusOZCLwmQHunoR4fc9OWEFbbaSGchVHwjpKkzYcwt3OlAkKvaLbKS5vz3HOBvXFi1b7bCnPdtIBsSfN2EOAKUtSqH7eHGtKzRHV4FNVuPZBXXReuxGfb3o2R90RKC23WhI6T5njWyaBZCm8LAgYOhQMZBZAISO4NBs6JiZCOPiW3kcoJSUumSI4aaTajZBpdqCyNXDSaJ7UUB7lAZDZD', 'token_type': 'bearer', 'expires_in': 5183821}
[2021-10-05 12:41:54] I facebo | TOKEN facebook_token: EAA6ysP2gQ0wBABp47teEdVs6HzvyNusOZCLwmQHunoR4fc9OWEFbbaSGchVHwjpKkzYcwt3OlAkKvaLbKS5vz3HOBvXFi1b7bCnPdtIBsSfN2EOAKUtSqH7eHGtKzRHV4FNVuPZBXXReuxGfb3o2R90RKC23WhI6T5njWyaBZCm8LAgYOhQMZBZAISO4NBs6JiZCOPiW3kcoJSUumSI4aaTajZBpdqCyNXDSaJ7UUB7lAZDZD
[2021-10-05 12:41:54] I facebo | CLAIMS me_endpoint: https://graph.facebook.com/me
[2021-10-05 12:41:54] I facebo | CLAIMS parameters: {'fields': 'name,email,picture,short_name', 'access_token': 'EAA6ysP2gQ0wBABp47teEdVs6HzvyNusOZCLwmQHunoR4fc9OWEFbbaSGchVHwjpKkzYcwt3OlAkKvaLbKS5vz3HOBvXFi1b7bCnPdtIBsSfN2EOAKUtSqH7eHGtKzRHV4FNVuPZBXXReuxGfb3o2R90RKC23WhI6T5njWyaBZCm8LAgYOhQMZBZAISO4NBs6JiZCOPiW3kcoJSUumSI4aaTajZBpdqCyNXDSaJ7UUB7lAZDZD'}
[2021-10-05 12:41:54] I facebo | CLAIMS me_response_json: {'name': 'Mykhailo Ogorodnikov', 'email': 'mi.ogoro@gmail.com', 'picture': {'data': {'height': 50, 'is_silhouette': False, 'url': 'https://platform-lookaside.fbsbx.com/platform/profilepic/?asid=4052844671451235&height=50&width=50&ext=1636029714&hash=AeR9vt5CBFSM8QYtNL8', 'width': 50}}, 'short_name': 'Mykhailo', 'id': '4052844671451235'}
[2021-10-05 12:43:53] I engine | Traceback (most recent call last):
  File "/home/ec2-user/environment/m1/app/core-service/core/engine.py", line 127, in wrapper
    return function(self, *args, **kwargs)
  File "/home/ec2-user/environment/m1/app/core-service/core/engine.py", line 159, in queue_worker
    time.sleep(1)
  File "/home/ec2-user/environment/m1/app/core-service/core/app.py", line 66, in termination_handler
    print(f'APP termination_handler signal {signal}, {frame}')
  File "/home/ec2-user/environment/m1/app/core-service/core/app.py", line 66, in termination_handler
    print(f'APP termination_handler signal {signal}, {frame}')
RuntimeError: reentrant call inside <_io.BufferedWriter name='<stdout>'>

[2021-10-05 12:48:20] I dynamo | DYNAMO initiated: <core.dynamo.DB object at 0x7efd5ac53cd0>
[2021-10-05 12:48:55] I dynamo | DYNAMO initiated: <core.dynamo.DB object at 0x7f8740e1ead0>
[2021-10-05 12:48:58] I engine | RUNNER initiated: <core.engine.Runner object at 0x7f8741a78ad0>
[2021-10-05 12:48:58] I engine | RUNNER queue_worker started: 15805
[2021-10-05 12:48:58] I engine | RUNNER started: <core.engine.Runner object at 0x7f8741a78ad0>
[2021-10-05 12:48:58] I telegr | BOT initiated: <core.telegram.Bot object at 0x7f8740b58950>
[2021-10-05 12:48:58] I telegr | BOT polling: <core.telegram.Bot object at 0x7f8740b58950>
[2021-10-05 12:48:58] I telegr | BOT enumerate_threads: [<_MainThread(MainThread, started 140219755280192)>, <Thread(QueueManagerThread, started daemon 140218882451200)>, <Thread(Telegram bot polling, started daemon 140218795550464)>, <Thread(QueueFeederThread, initial daemon)>]
[2021-10-05 12:48:58] I cognit | COGNITO initiated: <core.cognito.Users object at 0x7f8740aec310>
[2021-10-05 12:48:58] I facebo | FB initiated: <core.facebook.FB object at 0x7f8740aec350>
[2021-10-05 12:48:59] I engine | Traceback (most recent call last):
  File "/home/ec2-user/environment/m1/app/core-service/core/engine.py", line 127, in wrapper
    return function(self, *args, **kwargs)
  File "/home/ec2-user/environment/m1/app/core-service/core/engine.py", line 149, in get_next_task
    return self.db.get_next_task()
AttributeError: 'NoneType' object has no attribute 'get_next_task'

[2021-10-05 12:49:00] I engine | Traceback (most recent call last):
  File "/home/ec2-user/environment/m1/app/core-service/core/engine.py", line 127, in wrapper
    return function(self, *args, **kwargs)
  File "/home/ec2-user/environment/m1/app/core-service/core/engine.py", line 149, in get_next_task
    return self.db.get_next_task()
AttributeError: 'NoneType' object has no attribute 'get_next_task'

[2021-10-05 12:49:01] I engine | Traceback (most recent call last):
  File "/home/ec2-user/environment/m1/app/core-service/core/engine.py", line 127, in wrapper
    return function(self, *args, **kwargs)
  File "/home/ec2-user/environment/m1/app/core-service/core/engine.py", line 149, in get_next_task
    return self.db.get_next_task()
AttributeError: 'NoneType' object has no attribute 'get_next_task'

[2021-10-05 12:49:02] I engine | Traceback (most recent call last):
  File "/home/ec2-user/environment/m1/app/core-service/core/engine.py", line 127, in wrapper
    return function(self, *args, **kwargs)
  File "/home/ec2-user/environment/m1/app/core-service/core/engine.py", line 149, in get_next_task
    return self.db.get_next_task()
AttributeError: 'NoneType' object has no attribute 'get_next_task'

[2021-10-05 12:49:03] I engine | Traceback (most recent call last):
  File "/home/ec2-user/environment/m1/app/core-service/core/engine.py", line 127, in wrapper
    return function(self, *args, **kwargs)
  File "/home/ec2-user/environment/m1/app/core-service/core/engine.py", line 149, in get_next_task
    return self.db.get_next_task()
AttributeError: 'NoneType' object has no attribute 'get_next_task'

[2021-10-05 12:49:04] I engine | Traceback (most recent call last):
  File "/home/ec2-user/environment/m1/app/core-service/core/engine.py", line 127, in wrapper
    return function(self, *args, **kwargs)
  File "/home/ec2-user/environment/m1/app/core-service/core/engine.py", line 149, in get_next_task
    return self.db.get_next_task()
AttributeError: 'NoneType' object has no attribute 'get_next_task'

[2021-10-05 12:49:05] I engine | Traceback (most recent call last):
  File "/home/ec2-user/environment/m1/app/core-service/core/engine.py", line 127, in wrapper
    return function(self, *args, **kwargs)
  File "/home/ec2-user/environment/m1/app/core-service/core/engine.py", line 149, in get_next_task
    return self.db.get_next_task()
AttributeError: 'NoneType' object has no attribute 'get_next_task'

[2021-10-05 12:49:06] I engine | Traceback (most recent call last):
  File "/home/ec2-user/environment/m1/app/core-service/core/engine.py", line 127, in wrapper
    return function(self, *args, **kwargs)
  File "/home/ec2-user/environment/m1/app/core-service/core/engine.py", line 149, in get_next_task
    return self.db.get_next_task()
AttributeError: 'NoneType' object has no attribute 'get_next_task'

[2021-10-05 12:49:07] I engine | Traceback (most recent call last):
  File "/home/ec2-user/environment/m1/app/core-service/core/engine.py", line 127, in wrapper
    return function(self, *args, **kwargs)
  File "/home/ec2-user/environment/m1/app/core-service/core/engine.py", line 149, in get_next_task
    return self.db.get_next_task()
AttributeError: 'NoneType' object has no attribute 'get_next_task'

[2021-10-05 12:49:08] I engine | Traceback (most recent call last):
  File "/home/ec2-user/environment/m1/app/core-service/core/engine.py", line 127, in wrapper
    return function(self, *args, **kwargs)
  File "/home/ec2-user/environment/m1/app/core-service/core/engine.py", line 149, in get_next_task
    return self.db.get_next_task()
AttributeError: 'NoneType' object has no attribute 'get_next_task'

[2021-10-05 12:49:09] I engine | Traceback (most recent call last):
  File "/home/ec2-user/environment/m1/app/core-service/core/engine.py", line 127, in wrapper
    return function(self, *args, **kwargs)
  File "/home/ec2-user/environment/m1/app/core-service/core/engine.py", line 149, in get_next_task
    return self.db.get_next_task()
AttributeError: 'NoneType' object has no attribute 'get_next_task'

[2021-10-05 12:49:10] I engine | Traceback (most recent call last):
  File "/home/ec2-user/environment/m1/app/core-service/core/engine.py", line 127, in wrapper
    return function(self, *args, **kwargs)
  File "/home/ec2-user/environment/m1/app/core-service/core/engine.py", line 149, in get_next_task
    return self.db.get_next_task()
AttributeError: 'NoneType' object has no attribute 'get_next_task'

[2021-10-05 12:49:11] I engine | Traceback (most recent call last):
  File "/home/ec2-user/environment/m1/app/core-service/core/engine.py", line 127, in wrapper
    return function(self, *args, **kwargs)
  File "/home/ec2-user/environment/m1/app/core-service/core/engine.py", line 149, in get_next_task
    return self.db.get_next_task()
AttributeError: 'NoneType' object has no attribute 'get_next_task'

[2021-10-05 12:49:12] I engine | Traceback (most recent call last):
  File "/home/ec2-user/environment/m1/app/core-service/core/engine.py", line 127, in wrapper
    return function(self, *args, **kwargs)
  File "/home/ec2-user/environment/m1/app/core-service/core/engine.py", line 149, in get_next_task
    return self.db.get_next_task()
AttributeError: 'NoneType' object has no attribute 'get_next_task'

[2021-10-05 12:49:13] I engine | Traceback (most recent call last):
  File "/home/ec2-user/environment/m1/app/core-service/core/engine.py", line 127, in wrapper
    return function(self, *args, **kwargs)
  File "/home/ec2-user/environment/m1/app/core-service/core/engine.py", line 149, in get_next_task
    return self.db.get_next_task()
AttributeError: 'NoneType' object has no attribute 'get_next_task'

[2021-10-05 12:49:14] I engine | Traceback (most recent call last):
  File "/home/ec2-user/environment/m1/app/core-service/core/engine.py", line 127, in wrapper
    return function(self, *args, **kwargs)
  File "/home/ec2-user/environment/m1/app/core-service/core/engine.py", line 149, in get_next_task
    return self.db.get_next_task()
AttributeError: 'NoneType' object has no attribute 'get_next_task'

[2021-10-05 12:49:15] I engine | Traceback (most recent call last):
  File "/home/ec2-user/environment/m1/app/core-service/core/engine.py", line 127, in wrapper
    return function(self, *args, **kwargs)
  File "/home/ec2-user/environment/m1/app/core-service/core/engine.py", line 149, in get_next_task
    return self.db.get_next_task()
AttributeError: 'NoneType' object has no attribute 'get_next_task'

[2021-10-05 12:49:16] I engine | Traceback (most recent call last):
  File "/home/ec2-user/environment/m1/app/core-service/core/engine.py", line 127, in wrapper
    return function(self, *args, **kwargs)
  File "/home/ec2-user/environment/m1/app/core-service/core/engine.py", line 149, in get_next_task
    return self.db.get_next_task()
AttributeError: 'NoneType' object has no attribute 'get_next_task'

[2021-10-05 12:49:17] I engine | Traceback (most recent call last):
  File "/home/ec2-user/environment/m1/app/core-service/core/engine.py", line 127, in wrapper
    return function(self, *args, **kwargs)
  File "/home/ec2-user/environment/m1/app/core-service/core/engine.py", line 149, in get_next_task
    return self.db.get_next_task()
AttributeError: 'NoneType' object has no attribute 'get_next_task'

[2021-10-05 12:49:18] I engine | Traceback (most recent call last):
  File "/home/ec2-user/environment/m1/app/core-service/core/engine.py", line 127, in wrapper
    return function(self, *args, **kwargs)
  File "/home/ec2-user/environment/m1/app/core-service/core/engine.py", line 149, in get_next_task
    return self.db.get_next_task()
AttributeError: 'NoneType' object has no attribute 'get_next_task'

[2021-10-05 12:49:19] I engine | Traceback (most recent call last):
  File "/home/ec2-user/environment/m1/app/core-service/core/engine.py", line 127, in wrapper
    return function(self, *args, **kwargs)
  File "/home/ec2-user/environment/m1/app/core-service/core/engine.py", line 149, in get_next_task
    return self.db.get_next_task()
AttributeError: 'NoneType' object has no attribute 'get_next_task'

[2021-10-05 12:49:20] I engine | Traceback (most recent call last):
  File "/home/ec2-user/environment/m1/app/core-service/core/engine.py", line 127, in wrapper
    return function(self, *args, **kwargs)
  File "/home/ec2-user/environment/m1/app/core-service/core/engine.py", line 149, in get_next_task
    return self.db.get_next_task()
AttributeError: 'NoneType' object has no attribute 'get_next_task'

[2021-10-05 12:49:21] I engine | Traceback (most recent call last):
  File "/home/ec2-user/environment/m1/app/core-service/core/engine.py", line 127, in wrapper
    return function(self, *args, **kwargs)
  File "/home/ec2-user/environment/m1/app/core-service/core/engine.py", line 149, in get_next_task
    return self.db.get_next_task()
AttributeError: 'NoneType' object has no attribute 'get_next_task'

[2021-10-05 12:49:22] I engine | Traceback (most recent call last):
  File "/home/ec2-user/environment/m1/app/core-service/core/engine.py", line 127, in wrapper
    return function(self, *args, **kwargs)
  File "/home/ec2-user/environment/m1/app/core-service/core/engine.py", line 149, in get_next_task
    return self.db.get_next_task()
AttributeError: 'NoneType' object has no attribute 'get_next_task'

[2021-10-05 12:49:23] I engine | Traceback (most recent call last):
  File "/home/ec2-user/environment/m1/app/core-service/core/engine.py", line 127, in wrapper
    return function(self, *args, **kwargs)
  File "/home/ec2-user/environment/m1/app/core-service/core/engine.py", line 149, in get_next_task
    return self.db.get_next_task()
AttributeError: 'NoneType' object has no attribute 'get_next_task'

[2021-10-05 12:49:24] I engine | Traceback (most recent call last):
  File "/home/ec2-user/environment/m1/app/core-service/core/engine.py", line 127, in wrapper
    return function(self, *args, **kwargs)
  File "/home/ec2-user/environment/m1/app/core-service/core/engine.py", line 149, in get_next_task
    return self.db.get_next_task()
AttributeError: 'NoneType' object has no attribute 'get_next_task'

[2021-10-05 12:49:25] I engine | Traceback (most recent call last):
  File "/home/ec2-user/environment/m1/app/core-service/core/engine.py", line 127, in wrapper
    return function(self, *args, **kwargs)
  File "/home/ec2-user/environment/m1/app/core-service/core/engine.py", line 149, in get_next_task
    return self.db.get_next_task()
AttributeError: 'NoneType' object has no attribute 'get_next_task'

[2021-10-05 12:49:26] I engine | Traceback (most recent call last):
  File "/home/ec2-user/environment/m1/app/core-service/core/engine.py", line 127, in wrapper
    return function(self, *args, **kwargs)
  File "/home/ec2-user/environment/m1/app/core-service/core/engine.py", line 149, in get_next_task
    return self.db.get_next_task()
AttributeError: 'NoneType' object has no attribute 'get_next_task'

[2021-10-05 12:49:27] I engine | Traceback (most recent call last):
  File "/home/ec2-user/environment/m1/app/core-service/core/engine.py", line 127, in wrapper
    return function(self, *args, **kwargs)
  File "/home/ec2-user/environment/m1/app/core-service/core/engine.py", line 149, in get_next_task
    return self.db.get_next_task()
AttributeError: 'NoneType' object has no attribute 'get_next_task'

[2021-10-05 12:49:28] I engine | Traceback (most recent call last):
  File "/home/ec2-user/environment/m1/app/core-service/core/engine.py", line 127, in wrapper
    return function(self, *args, **kwargs)
  File "/home/ec2-user/environment/m1/app/core-service/core/engine.py", line 149, in get_next_task
    return self.db.get_next_task()
AttributeError: 'NoneType' object has no attribute 'get_next_task'

[2021-10-05 12:49:29] I engine | Traceback (most recent call last):
  File "/home/ec2-user/environment/m1/app/core-service/core/engine.py", line 127, in wrapper
    return function(self, *args, **kwargs)
  File "/home/ec2-user/environment/m1/app/core-service/core/engine.py", line 149, in get_next_task
    return self.db.get_next_task()
AttributeError: 'NoneType' object has no attribute 'get_next_task'

[2021-10-05 12:49:30] I engine | Traceback (most recent call last):
  File "/home/ec2-user/environment/m1/app/core-service/core/engine.py", line 127, in wrapper
    return function(self, *args, **kwargs)
  File "/home/ec2-user/environment/m1/app/core-service/core/engine.py", line 149, in get_next_task
    return self.db.get_next_task()
AttributeError: 'NoneType' object has no attribute 'get_next_task'

[2021-10-05 12:49:31] I engine | Traceback (most recent call last):
  File "/home/ec2-user/environment/m1/app/core-service/core/engine.py", line 127, in wrapper
    return function(self, *args, **kwargs)
  File "/home/ec2-user/environment/m1/app/core-service/core/engine.py", line 149, in get_next_task
    return self.db.get_next_task()
AttributeError: 'NoneType' object has no attribute 'get_next_task'

[2021-10-05 12:49:32] I engine | Traceback (most recent call last):
  File "/home/ec2-user/environment/m1/app/core-service/core/engine.py", line 127, in wrapper
    return function(self, *args, **kwargs)
  File "/home/ec2-user/environment/m1/app/core-service/core/engine.py", line 149, in get_next_task
    return self.db.get_next_task()
AttributeError: 'NoneType' object has no attribute 'get_next_task'

[2021-10-05 12:49:33] I engine | Traceback (most recent call last):
  File "/home/ec2-user/environment/m1/app/core-service/core/engine.py", line 127, in wrapper
    return function(self, *args, **kwargs)
  File "/home/ec2-user/environment/m1/app/core-service/core/engine.py", line 149, in get_next_task
    return self.db.get_next_task()
AttributeError: 'NoneType' object has no attribute 'get_next_task'

[2021-10-05 12:49:34] I engine | Traceback (most recent call last):
  File "/home/ec2-user/environment/m1/app/core-service/core/engine.py", line 127, in wrapper
    return function(self, *args, **kwargs)
  File "/home/ec2-user/environment/m1/app/core-service/core/engine.py", line 149, in get_next_task
    return self.db.get_next_task()
AttributeError: 'NoneType' object has no attribute 'get_next_task'

[2021-10-05 12:49:35] I engine | Traceback (most recent call last):
  File "/home/ec2-user/environment/m1/app/core-service/core/engine.py", line 127, in wrapper
    return function(self, *args, **kwargs)
  File "/home/ec2-user/environment/m1/app/core-service/core/engine.py", line 149, in get_next_task
    return self.db.get_next_task()
AttributeError: 'NoneType' object has no attribute 'get_next_task'

[2021-10-05 12:49:36] I engine | Traceback (most recent call last):
  File "/home/ec2-user/environment/m1/app/core-service/core/engine.py", line 127, in wrapper
    return function(self, *args, **kwargs)
  File "/home/ec2-user/environment/m1/app/core-service/core/engine.py", line 149, in get_next_task
    return self.db.get_next_task()
AttributeError: 'NoneType' object has no attribute 'get_next_task'

[2021-10-05 12:49:37] I engine | Traceback (most recent call last):
  File "/home/ec2-user/environment/m1/app/core-service/core/engine.py", line 127, in wrapper
    return function(self, *args, **kwargs)
  File "/home/ec2-user/environment/m1/app/core-service/core/engine.py", line 149, in get_next_task
    return self.db.get_next_task()
AttributeError: 'NoneType' object has no attribute 'get_next_task'

[2021-10-05 12:49:38] I engine | Traceback (most recent call last):
  File "/home/ec2-user/environment/m1/app/core-service/core/engine.py", line 127, in wrapper
    return function(self, *args, **kwargs)
  File "/home/ec2-user/environment/m1/app/core-service/core/engine.py", line 149, in get_next_task
    return self.db.get_next_task()
AttributeError: 'NoneType' object has no attribute 'get_next_task'

[2021-10-05 12:49:39] I engine | Traceback (most recent call last):
  File "/home/ec2-user/environment/m1/app/core-service/core/engine.py", line 127, in wrapper
    return function(self, *args, **kwargs)
  File "/home/ec2-user/environment/m1/app/core-service/core/engine.py", line 149, in get_next_task
    return self.db.get_next_task()
AttributeError: 'NoneType' object has no attribute 'get_next_task'

[2021-10-05 12:49:40] I engine | Traceback (most recent call last):
  File "/home/ec2-user/environment/m1/app/core-service/core/engine.py", line 127, in wrapper
    return function(self, *args, **kwargs)
  File "/home/ec2-user/environment/m1/app/core-service/core/engine.py", line 149, in get_next_task
    return self.db.get_next_task()
AttributeError: 'NoneType' object has no attribute 'get_next_task'

[2021-10-05 12:49:41] I engine | Traceback (most recent call last):
  File "/home/ec2-user/environment/m1/app/core-service/core/engine.py", line 127, in wrapper
    return function(self, *args, **kwargs)
  File "/home/ec2-user/environment/m1/app/core-service/core/engine.py", line 149, in get_next_task
    return self.db.get_next_task()
AttributeError: 'NoneType' object has no attribute 'get_next_task'

[2021-10-05 12:49:42] I engine | Traceback (most recent call last):
  File "/home/ec2-user/environment/m1/app/core-service/core/engine.py", line 127, in wrapper
    return function(self, *args, **kwargs)
  File "/home/ec2-user/environment/m1/app/core-service/core/engine.py", line 149, in get_next_task
    return self.db.get_next_task()
AttributeError: 'NoneType' object has no attribute 'get_next_task'

[2021-10-05 12:49:43] I engine | Traceback (most recent call last):
  File "/home/ec2-user/environment/m1/app/core-service/core/engine.py", line 127, in wrapper
    return function(self, *args, **kwargs)
  File "/home/ec2-user/environment/m1/app/core-service/core/engine.py", line 149, in get_next_task
    return self.db.get_next_task()
AttributeError: 'NoneType' object has no attribute 'get_next_task'

[2021-10-05 12:49:44] I engine | Traceback (most recent call last):
  File "/home/ec2-user/environment/m1/app/core-service/core/engine.py", line 127, in wrapper
    return function(self, *args, **kwargs)
  File "/home/ec2-user/environment/m1/app/core-service/core/engine.py", line 149, in get_next_task
    return self.db.get_next_task()
AttributeError: 'NoneType' object has no attribute 'get_next_task'

[2021-10-05 12:49:45] I engine | Traceback (most recent call last):
  File "/home/ec2-user/environment/m1/app/core-service/core/engine.py", line 127, in wrapper
    return function(self, *args, **kwargs)
  File "/home/ec2-user/environment/m1/app/core-service/core/engine.py", line 149, in get_next_task
    return self.db.get_next_task()
AttributeError: 'NoneType' object has no attribute 'get_next_task'

[2021-10-05 12:49:46] I engine | Traceback (most recent call last):
  File "/home/ec2-user/environment/m1/app/core-service/core/engine.py", line 127, in wrapper
    return function(self, *args, **kwargs)
  File "/home/ec2-user/environment/m1/app/core-service/core/engine.py", line 149, in get_next_task
    return self.db.get_next_task()
AttributeError: 'NoneType' object has no attribute 'get_next_task'

[2021-10-05 12:49:47] I engine | Traceback (most recent call last):
  File "/home/ec2-user/environment/m1/app/core-service/core/engine.py", line 127, in wrapper
    return function(self, *args, **kwargs)
  File "/home/ec2-user/environment/m1/app/core-service/core/engine.py", line 149, in get_next_task
    return self.db.get_next_task()
AttributeError: 'NoneType' object has no attribute 'get_next_task'

[2021-10-05 12:49:48] I engine | Traceback (most recent call last):
  File "/home/ec2-user/environment/m1/app/core-service/core/engine.py", line 127, in wrapper
    return function(self, *args, **kwargs)
  File "/home/ec2-user/environment/m1/app/core-service/core/engine.py", line 149, in get_next_task
    return self.db.get_next_task()
AttributeError: 'NoneType' object has no attribute 'get_next_task'

[2021-10-05 12:49:49] I engine | Traceback (most recent call last):
  File "/home/ec2-user/environment/m1/app/core-service/core/engine.py", line 127, in wrapper
    return function(self, *args, **kwargs)
  File "/home/ec2-user/environment/m1/app/core-service/core/engine.py", line 149, in get_next_task
    return self.db.get_next_task()
AttributeError: 'NoneType' object has no attribute 'get_next_task'

[2021-10-05 12:49:50] I engine | Traceback (most recent call last):
  File "/home/ec2-user/environment/m1/app/core-service/core/engine.py", line 127, in wrapper
    return function(self, *args, **kwargs)
  File "/home/ec2-user/environment/m1/app/core-service/core/engine.py", line 149, in get_next_task
    return self.db.get_next_task()
AttributeError: 'NoneType' object has no attribute 'get_next_task'

[2021-10-05 12:49:51] I engine | Traceback (most recent call last):
  File "/home/ec2-user/environment/m1/app/core-service/core/engine.py", line 127, in wrapper
    return function(self, *args, **kwargs)
  File "/home/ec2-user/environment/m1/app/core-service/core/engine.py", line 149, in get_next_task
    return self.db.get_next_task()
AttributeError: 'NoneType' object has no attribute 'get_next_task'

[2021-10-05 12:49:52] I engine | Traceback (most recent call last):
  File "/home/ec2-user/environment/m1/app/core-service/core/engine.py", line 127, in wrapper
    return function(self, *args, **kwargs)
  File "/home/ec2-user/environment/m1/app/core-service/core/engine.py", line 149, in get_next_task
    return self.db.get_next_task()
AttributeError: 'NoneType' object has no attribute 'get_next_task'

[2021-10-05 12:49:53] I engine | Traceback (most recent call last):
  File "/home/ec2-user/environment/m1/app/core-service/core/engine.py", line 127, in wrapper
    return function(self, *args, **kwargs)
  File "/home/ec2-user/environment/m1/app/core-service/core/engine.py", line 149, in get_next_task
    return self.db.get_next_task()
AttributeError: 'NoneType' object has no attribute 'get_next_task'

[2021-10-05 12:49:54] I engine | Traceback (most recent call last):
  File "/home/ec2-user/environment/m1/app/core-service/core/engine.py", line 127, in wrapper
    return function(self, *args, **kwargs)
  File "/home/ec2-user/environment/m1/app/core-service/core/engine.py", line 149, in get_next_task
    return self.db.get_next_task()
AttributeError: 'NoneType' object has no attribute 'get_next_task'

[2021-10-05 12:49:55] I engine | Traceback (most recent call last):
  File "/home/ec2-user/environment/m1/app/core-service/core/engine.py", line 127, in wrapper
    return function(self, *args, **kwargs)
  File "/home/ec2-user/environment/m1/app/core-service/core/engine.py", line 149, in get_next_task
    return self.db.get_next_task()
AttributeError: 'NoneType' object has no attribute 'get_next_task'

[2021-10-05 12:49:56] I engine | Traceback (most recent call last):
  File "/home/ec2-user/environment/m1/app/core-service/core/engine.py", line 127, in wrapper
    return function(self, *args, **kwargs)
  File "/home/ec2-user/environment/m1/app/core-service/core/engine.py", line 149, in get_next_task
    return self.db.get_next_task()
AttributeError: 'NoneType' object has no attribute 'get_next_task'

[2021-10-05 12:49:57] I engine | Traceback (most recent call last):
  File "/home/ec2-user/environment/m1/app/core-service/core/engine.py", line 127, in wrapper
    return function(self, *args, **kwargs)
  File "/home/ec2-user/environment/m1/app/core-service/core/engine.py", line 149, in get_next_task
    return self.db.get_next_task()
AttributeError: 'NoneType' object has no attribute 'get_next_task'

[2021-10-05 12:49:58] I engine | Traceback (most recent call last):
  File "/home/ec2-user/environment/m1/app/core-service/core/engine.py", line 127, in wrapper
    return function(self, *args, **kwargs)
  File "/home/ec2-user/environment/m1/app/core-service/core/engine.py", line 149, in get_next_task
    return self.db.get_next_task()
AttributeError: 'NoneType' object has no attribute 'get_next_task'

[2021-10-05 12:49:59] I engine | Traceback (most recent call last):
  File "/home/ec2-user/environment/m1/app/core-service/core/engine.py", line 127, in wrapper
    return function(self, *args, **kwargs)
  File "/home/ec2-user/environment/m1/app/core-service/core/engine.py", line 149, in get_next_task
    return self.db.get_next_task()
AttributeError: 'NoneType' object has no attribute 'get_next_task'

[2021-10-05 12:50:00] I engine | Traceback (most recent call last):
  File "/home/ec2-user/environment/m1/app/core-service/core/engine.py", line 127, in wrapper
    return function(self, *args, **kwargs)
  File "/home/ec2-user/environment/m1/app/core-service/core/engine.py", line 149, in get_next_task
    return self.db.get_next_task()
AttributeError: 'NoneType' object has no attribute 'get_next_task'

[2021-10-05 12:50:01] I engine | Traceback (most recent call last):
  File "/home/ec2-user/environment/m1/app/core-service/core/engine.py", line 127, in wrapper
    return function(self, *args, **kwargs)
  File "/home/ec2-user/environment/m1/app/core-service/core/engine.py", line 149, in get_next_task
    return self.db.get_next_task()
AttributeError: 'NoneType' object has no attribute 'get_next_task'

[2021-10-05 12:50:02] I engine | Traceback (most recent call last):
  File "/home/ec2-user/environment/m1/app/core-service/core/engine.py", line 127, in wrapper
    return function(self, *args, **kwargs)
  File "/home/ec2-user/environment/m1/app/core-service/core/engine.py", line 149, in get_next_task
    return self.db.get_next_task()
AttributeError: 'NoneType' object has no attribute 'get_next_task'

[2021-10-05 12:50:03] I engine | Traceback (most recent call last):
  File "/home/ec2-user/environment/m1/app/core-service/core/engine.py", line 127, in wrapper
    return function(self, *args, **kwargs)
  File "/home/ec2-user/environment/m1/app/core-service/core/engine.py", line 149, in get_next_task
    return self.db.get_next_task()
AttributeError: 'NoneType' object has no attribute 'get_next_task'

[2021-10-05 12:50:04] I engine | Traceback (most recent call last):
  File "/home/ec2-user/environment/m1/app/core-service/core/engine.py", line 127, in wrapper
    return function(self, *args, **kwargs)
  File "/home/ec2-user/environment/m1/app/core-service/core/engine.py", line 149, in get_next_task
    return self.db.get_next_task()
AttributeError: 'NoneType' object has no attribute 'get_next_task'

[2021-10-05 12:50:05] I engine | Traceback (most recent call last):
  File "/home/ec2-user/environment/m1/app/core-service/core/engine.py", line 127, in wrapper
    return function(self, *args, **kwargs)
  File "/home/ec2-user/environment/m1/app/core-service/core/engine.py", line 149, in get_next_task
    return self.db.get_next_task()
AttributeError: 'NoneType' object has no attribute 'get_next_task'

[2021-10-05 12:50:06] I engine | Traceback (most recent call last):
  File "/home/ec2-user/environment/m1/app/core-service/core/engine.py", line 127, in wrapper
    return function(self, *args, **kwargs)
  File "/home/ec2-user/environment/m1/app/core-service/core/engine.py", line 149, in get_next_task
    return self.db.get_next_task()
AttributeError: 'NoneType' object has no attribute 'get_next_task'

[2021-10-05 12:50:07] I engine | Traceback (most recent call last):
  File "/home/ec2-user/environment/m1/app/core-service/core/engine.py", line 127, in wrapper
    return function(self, *args, **kwargs)
  File "/home/ec2-user/environment/m1/app/core-service/core/engine.py", line 149, in get_next_task
    return self.db.get_next_task()
AttributeError: 'NoneType' object has no attribute 'get_next_task'

[2021-10-05 12:50:08] I engine | Traceback (most recent call last):
  File "/home/ec2-user/environment/m1/app/core-service/core/engine.py", line 127, in wrapper
    return function(self, *args, **kwargs)
  File "/home/ec2-user/environment/m1/app/core-service/core/engine.py", line 149, in get_next_task
    return self.db.get_next_task()
AttributeError: 'NoneType' object has no attribute 'get_next_task'

[2021-10-05 12:50:09] I engine | Traceback (most recent call last):
  File "/home/ec2-user/environment/m1/app/core-service/core/engine.py", line 127, in wrapper
    return function(self, *args, **kwargs)
  File "/home/ec2-user/environment/m1/app/core-service/core/engine.py", line 149, in get_next_task
    return self.db.get_next_task()
AttributeError: 'NoneType' object has no attribute 'get_next_task'

[2021-10-05 12:50:10] I engine | Traceback (most recent call last):
  File "/home/ec2-user/environment/m1/app/core-service/core/engine.py", line 127, in wrapper
    return function(self, *args, **kwargs)
  File "/home/ec2-user/environment/m1/app/core-service/core/engine.py", line 149, in get_next_task
    return self.db.get_next_task()
AttributeError: 'NoneType' object has no attribute 'get_next_task'

[2021-10-05 12:50:11] I engine | Traceback (most recent call last):
  File "/home/ec2-user/environment/m1/app/core-service/core/engine.py", line 127, in wrapper
    return function(self, *args, **kwargs)
  File "/home/ec2-user/environment/m1/app/core-service/core/engine.py", line 149, in get_next_task
    return self.db.get_next_task()
AttributeError: 'NoneType' object has no attribute 'get_next_task'

[2021-10-05 12:50:12] I engine | Traceback (most recent call last):
  File "/home/ec2-user/environment/m1/app/core-service/core/engine.py", line 127, in wrapper
    return function(self, *args, **kwargs)
  File "/home/ec2-user/environment/m1/app/core-service/core/engine.py", line 149, in get_next_task
    return self.db.get_next_task()
AttributeError: 'NoneType' object has no attribute 'get_next_task'

[2021-10-05 12:50:13] I engine | Traceback (most recent call last):
  File "/home/ec2-user/environment/m1/app/core-service/core/engine.py", line 127, in wrapper
    return function(self, *args, **kwargs)
  File "/home/ec2-user/environment/m1/app/core-service/core/engine.py", line 149, in get_next_task
    return self.db.get_next_task()
AttributeError: 'NoneType' object has no attribute 'get_next_task'

[2021-10-05 12:50:14] I engine | Traceback (most recent call last):
  File "/home/ec2-user/environment/m1/app/core-service/core/engine.py", line 127, in wrapper
    return function(self, *args, **kwargs)
  File "/home/ec2-user/environment/m1/app/core-service/core/engine.py", line 149, in get_next_task
    return self.db.get_next_task()
AttributeError: 'NoneType' object has no attribute 'get_next_task'

[2021-10-05 12:50:15] I engine | Traceback (most recent call last):
  File "/home/ec2-user/environment/m1/app/core-service/core/engine.py", line 127, in wrapper
    return function(self, *args, **kwargs)
  File "/home/ec2-user/environment/m1/app/core-service/core/engine.py", line 149, in get_next_task
    return self.db.get_next_task()
AttributeError: 'NoneType' object has no attribute 'get_next_task'

[2021-10-05 12:50:16] I engine | Traceback (most recent call last):
  File "/home/ec2-user/environment/m1/app/core-service/core/engine.py", line 127, in wrapper
    return function(self, *args, **kwargs)
  File "/home/ec2-user/environment/m1/app/core-service/core/engine.py", line 149, in get_next_task
    return self.db.get_next_task()
AttributeError: 'NoneType' object has no attribute 'get_next_task'

[2021-10-05 12:50:17] I engine | Traceback (most recent call last):
  File "/home/ec2-user/environment/m1/app/core-service/core/engine.py", line 127, in wrapper
    return function(self, *args, **kwargs)
  File "/home/ec2-user/environment/m1/app/core-service/core/engine.py", line 149, in get_next_task
    return self.db.get_next_task()
AttributeError: 'NoneType' object has no attribute 'get_next_task'

[2021-10-05 12:50:18] I engine | Traceback (most recent call last):
  File "/home/ec2-user/environment/m1/app/core-service/core/engine.py", line 127, in wrapper
    return function(self, *args, **kwargs)
  File "/home/ec2-user/environment/m1/app/core-service/core/engine.py", line 149, in get_next_task
    return self.db.get_next_task()
AttributeError: 'NoneType' object has no attribute 'get_next_task'

[2021-10-05 12:50:19] I engine | Traceback (most recent call last):
  File "/home/ec2-user/environment/m1/app/core-service/core/engine.py", line 127, in wrapper
    return function(self, *args, **kwargs)
  File "/home/ec2-user/environment/m1/app/core-service/core/engine.py", line 149, in get_next_task
    return self.db.get_next_task()
AttributeError: 'NoneType' object has no attribute 'get_next_task'

[2021-10-05 12:50:20] I engine | Traceback (most recent call last):
  File "/home/ec2-user/environment/m1/app/core-service/core/engine.py", line 127, in wrapper
    return function(self, *args, **kwargs)
  File "/home/ec2-user/environment/m1/app/core-service/core/engine.py", line 149, in get_next_task
    return self.db.get_next_task()
AttributeError: 'NoneType' object has no attribute 'get_next_task'

[2021-10-05 12:50:21] I engine | Traceback (most recent call last):
  File "/home/ec2-user/environment/m1/app/core-service/core/engine.py", line 127, in wrapper
    return function(self, *args, **kwargs)
  File "/home/ec2-user/environment/m1/app/core-service/core/engine.py", line 149, in get_next_task
    return self.db.get_next_task()
AttributeError: 'NoneType' object has no attribute 'get_next_task'

[2021-10-05 12:50:22] I engine | Traceback (most recent call last):
  File "/home/ec2-user/environment/m1/app/core-service/core/engine.py", line 127, in wrapper
    return function(self, *args, **kwargs)
  File "/home/ec2-user/environment/m1/app/core-service/core/engine.py", line 149, in get_next_task
    return self.db.get_next_task()
AttributeError: 'NoneType' object has no attribute 'get_next_task'

[2021-10-05 12:50:23] I engine | Traceback (most recent call last):
  File "/home/ec2-user/environment/m1/app/core-service/core/engine.py", line 127, in wrapper
    return function(self, *args, **kwargs)
  File "/home/ec2-user/environment/m1/app/core-service/core/engine.py", line 149, in get_next_task
    return self.db.get_next_task()
AttributeError: 'NoneType' object has no attribute 'get_next_task'

[2021-10-05 12:50:24] I engine | Traceback (most recent call last):
  File "/home/ec2-user/environment/m1/app/core-service/core/engine.py", line 127, in wrapper
    return function(self, *args, **kwargs)
  File "/home/ec2-user/environment/m1/app/core-service/core/engine.py", line 149, in get_next_task
    return self.db.get_next_task()
AttributeError: 'NoneType' object has no attribute 'get_next_task'

[2021-10-05 12:50:25] I engine | Traceback (most recent call last):
  File "/home/ec2-user/environment/m1/app/core-service/core/engine.py", line 127, in wrapper
    return function(self, *args, **kwargs)
  File "/home/ec2-user/environment/m1/app/core-service/core/engine.py", line 149, in get_next_task
    return self.db.get_next_task()
AttributeError: 'NoneType' object has no attribute 'get_next_task'

[2021-10-05 12:50:26] I engine | Traceback (most recent call last):
  File "/home/ec2-user/environment/m1/app/core-service/core/engine.py", line 127, in wrapper
    return function(self, *args, **kwargs)
  File "/home/ec2-user/environment/m1/app/core-service/core/engine.py", line 149, in get_next_task
    return self.db.get_next_task()
AttributeError: 'NoneType' object has no attribute 'get_next_task'

[2021-10-05 12:50:27] I engine | Traceback (most recent call last):
  File "/home/ec2-user/environment/m1/app/core-service/core/engine.py", line 127, in wrapper
    return function(self, *args, **kwargs)
  File "/home/ec2-user/environment/m1/app/core-service/core/engine.py", line 149, in get_next_task
    return self.db.get_next_task()
AttributeError: 'NoneType' object has no attribute 'get_next_task'

[2021-10-05 12:50:28] I engine | Traceback (most recent call last):
  File "/home/ec2-user/environment/m1/app/core-service/core/engine.py", line 127, in wrapper
    return function(self, *args, **kwargs)
  File "/home/ec2-user/environment/m1/app/core-service/core/engine.py", line 149, in get_next_task
    return self.db.get_next_task()
AttributeError: 'NoneType' object has no attribute 'get_next_task'

[2021-10-05 12:50:29] I engine | Traceback (most recent call last):
  File "/home/ec2-user/environment/m1/app/core-service/core/engine.py", line 127, in wrapper
    return function(self, *args, **kwargs)
  File "/home/ec2-user/environment/m1/app/core-service/core/engine.py", line 149, in get_next_task
    return self.db.get_next_task()
AttributeError: 'NoneType' object has no attribute 'get_next_task'

[2021-10-05 12:50:30] I engine | Traceback (most recent call last):
  File "/home/ec2-user/environment/m1/app/core-service/core/engine.py", line 127, in wrapper
    return function(self, *args, **kwargs)
  File "/home/ec2-user/environment/m1/app/core-service/core/engine.py", line 149, in get_next_task
    return self.db.get_next_task()
AttributeError: 'NoneType' object has no attribute 'get_next_task'

[2021-10-05 12:50:31] I engine | Traceback (most recent call last):
  File "/home/ec2-user/environment/m1/app/core-service/core/engine.py", line 127, in wrapper
    return function(self, *args, **kwargs)
  File "/home/ec2-user/environment/m1/app/core-service/core/engine.py", line 149, in get_next_task
    return self.db.get_next_task()
AttributeError: 'NoneType' object has no attribute 'get_next_task'

[2021-10-05 12:50:32] I engine | Traceback (most recent call last):
  File "/home/ec2-user/environment/m1/app/core-service/core/engine.py", line 127, in wrapper
    return function(self, *args, **kwargs)
  File "/home/ec2-user/environment/m1/app/core-service/core/engine.py", line 149, in get_next_task
    return self.db.get_next_task()
AttributeError: 'NoneType' object has no attribute 'get_next_task'

[2021-10-05 12:50:33] I engine | Traceback (most recent call last):
  File "/home/ec2-user/environment/m1/app/core-service/core/engine.py", line 127, in wrapper
    return function(self, *args, **kwargs)
  File "/home/ec2-user/environment/m1/app/core-service/core/engine.py", line 149, in get_next_task
    return self.db.get_next_task()
AttributeError: 'NoneType' object has no attribute 'get_next_task'

[2021-10-05 12:50:34] I engine | Traceback (most recent call last):
  File "/home/ec2-user/environment/m1/app/core-service/core/engine.py", line 127, in wrapper
    return function(self, *args, **kwargs)
  File "/home/ec2-user/environment/m1/app/core-service/core/engine.py", line 149, in get_next_task
    return self.db.get_next_task()
AttributeError: 'NoneType' object has no attribute 'get_next_task'

[2021-10-05 12:50:35] I engine | Traceback (most recent call last):
  File "/home/ec2-user/environment/m1/app/core-service/core/engine.py", line 127, in wrapper
    return function(self, *args, **kwargs)
  File "/home/ec2-user/environment/m1/app/core-service/core/engine.py", line 149, in get_next_task
    return self.db.get_next_task()
AttributeError: 'NoneType' object has no attribute 'get_next_task'

[2021-10-05 12:50:36] I engine | Traceback (most recent call last):
  File "/home/ec2-user/environment/m1/app/core-service/core/engine.py", line 127, in wrapper
    return function(self, *args, **kwargs)
  File "/home/ec2-user/environment/m1/app/core-service/core/engine.py", line 149, in get_next_task
    return self.db.get_next_task()
AttributeError: 'NoneType' object has no attribute 'get_next_task'

[2021-10-05 12:50:37] I engine | Traceback (most recent call last):
  File "/home/ec2-user/environment/m1/app/core-service/core/engine.py", line 127, in wrapper
    return function(self, *args, **kwargs)
  File "/home/ec2-user/environment/m1/app/core-service/core/engine.py", line 149, in get_next_task
    return self.db.get_next_task()
AttributeError: 'NoneType' object has no attribute 'get_next_task'

[2021-10-05 12:50:38] I engine | Traceback (most recent call last):
  File "/home/ec2-user/environment/m1/app/core-service/core/engine.py", line 127, in wrapper
    return function(self, *args, **kwargs)
  File "/home/ec2-user/environment/m1/app/core-service/core/engine.py", line 149, in get_next_task
    return self.db.get_next_task()
AttributeError: 'NoneType' object has no attribute 'get_next_task'

[2021-10-05 12:50:39] I engine | Traceback (most recent call last):
  File "/home/ec2-user/environment/m1/app/core-service/core/engine.py", line 127, in wrapper
    return function(self, *args, **kwargs)
  File "/home/ec2-user/environment/m1/app/core-service/core/engine.py", line 149, in get_next_task
    return self.db.get_next_task()
AttributeError: 'NoneType' object has no attribute 'get_next_task'

[2021-10-05 12:50:40] I engine | Traceback (most recent call last):
  File "/home/ec2-user/environment/m1/app/core-service/core/engine.py", line 127, in wrapper
    return function(self, *args, **kwargs)
  File "/home/ec2-user/environment/m1/app/core-service/core/engine.py", line 149, in get_next_task
    return self.db.get_next_task()
AttributeError: 'NoneType' object has no attribute 'get_next_task'

[2021-10-05 12:50:41] I engine | Traceback (most recent call last):
  File "/home/ec2-user/environment/m1/app/core-service/core/engine.py", line 127, in wrapper
    return function(self, *args, **kwargs)
  File "/home/ec2-user/environment/m1/app/core-service/core/engine.py", line 149, in get_next_task
    return self.db.get_next_task()
AttributeError: 'NoneType' object has no attribute 'get_next_task'

[2021-10-05 12:50:42] I engine | Traceback (most recent call last):
  File "/home/ec2-user/environment/m1/app/core-service/core/engine.py", line 127, in wrapper
    return function(self, *args, **kwargs)
  File "/home/ec2-user/environment/m1/app/core-service/core/engine.py", line 149, in get_next_task
    return self.db.get_next_task()
AttributeError: 'NoneType' object has no attribute 'get_next_task'

[2021-10-05 12:50:43] I engine | Traceback (most recent call last):
  File "/home/ec2-user/environment/m1/app/core-service/core/engine.py", line 127, in wrapper
    return function(self, *args, **kwargs)
  File "/home/ec2-user/environment/m1/app/core-service/core/engine.py", line 149, in get_next_task
    return self.db.get_next_task()
AttributeError: 'NoneType' object has no attribute 'get_next_task'

[2021-10-05 12:50:44] I engine | Traceback (most recent call last):
  File "/home/ec2-user/environment/m1/app/core-service/core/engine.py", line 127, in wrapper
    return function(self, *args, **kwargs)
  File "/home/ec2-user/environment/m1/app/core-service/core/engine.py", line 149, in get_next_task
    return self.db.get_next_task()
AttributeError: 'NoneType' object has no attribute 'get_next_task'

[2021-10-05 12:50:45] I engine | Traceback (most recent call last):
  File "/home/ec2-user/environment/m1/app/core-service/core/engine.py", line 127, in wrapper
    return function(self, *args, **kwargs)
  File "/home/ec2-user/environment/m1/app/core-service/core/engine.py", line 149, in get_next_task
    return self.db.get_next_task()
AttributeError: 'NoneType' object has no attribute 'get_next_task'

[2021-10-05 12:50:46] I engine | Traceback (most recent call last):
  File "/home/ec2-user/environment/m1/app/core-service/core/engine.py", line 127, in wrapper
    return function(self, *args, **kwargs)
  File "/home/ec2-user/environment/m1/app/core-service/core/engine.py", line 149, in get_next_task
    return self.db.get_next_task()
AttributeError: 'NoneType' object has no attribute 'get_next_task'

[2021-10-05 12:50:47] I engine | Traceback (most recent call last):
  File "/home/ec2-user/environment/m1/app/core-service/core/engine.py", line 127, in wrapper
    return function(self, *args, **kwargs)
  File "/home/ec2-user/environment/m1/app/core-service/core/engine.py", line 149, in get_next_task
    return self.db.get_next_task()
AttributeError: 'NoneType' object has no attribute 'get_next_task'

[2021-10-05 12:50:48] I engine | Traceback (most recent call last):
  File "/home/ec2-user/environment/m1/app/core-service/core/engine.py", line 127, in wrapper
    return function(self, *args, **kwargs)
  File "/home/ec2-user/environment/m1/app/core-service/core/engine.py", line 149, in get_next_task
    return self.db.get_next_task()
AttributeError: 'NoneType' object has no attribute 'get_next_task'

[2021-10-05 12:50:49] I engine | Traceback (most recent call last):
  File "/home/ec2-user/environment/m1/app/core-service/core/engine.py", line 127, in wrapper
    return function(self, *args, **kwargs)
  File "/home/ec2-user/environment/m1/app/core-service/core/engine.py", line 149, in get_next_task
    return self.db.get_next_task()
AttributeError: 'NoneType' object has no attribute 'get_next_task'

[2021-10-05 12:50:50] I engine | Traceback (most recent call last):
  File "/home/ec2-user/environment/m1/app/core-service/core/engine.py", line 127, in wrapper
    return function(self, *args, **kwargs)
  File "/home/ec2-user/environment/m1/app/core-service/core/engine.py", line 149, in get_next_task
    return self.db.get_next_task()
AttributeError: 'NoneType' object has no attribute 'get_next_task'

[2021-10-05 12:50:51] I engine | Traceback (most recent call last):
  File "/home/ec2-user/environment/m1/app/core-service/core/engine.py", line 127, in wrapper
    return function(self, *args, **kwargs)
  File "/home/ec2-user/environment/m1/app/core-service/core/engine.py", line 149, in get_next_task
    return self.db.get_next_task()
AttributeError: 'NoneType' object has no attribute 'get_next_task'

[2021-10-05 12:50:52] I engine | Traceback (most recent call last):
  File "/home/ec2-user/environment/m1/app/core-service/core/engine.py", line 127, in wrapper
    return function(self, *args, **kwargs)
  File "/home/ec2-user/environment/m1/app/core-service/core/engine.py", line 149, in get_next_task
    return self.db.get_next_task()
AttributeError: 'NoneType' object has no attribute 'get_next_task'

[2021-10-05 12:50:53] I engine | Traceback (most recent call last):
  File "/home/ec2-user/environment/m1/app/core-service/core/engine.py", line 127, in wrapper
    return function(self, *args, **kwargs)
  File "/home/ec2-user/environment/m1/app/core-service/core/engine.py", line 149, in get_next_task
    return self.db.get_next_task()
AttributeError: 'NoneType' object has no attribute 'get_next_task'

[2021-10-05 12:50:54] I engine | Traceback (most recent call last):
  File "/home/ec2-user/environment/m1/app/core-service/core/engine.py", line 127, in wrapper
    return function(self, *args, **kwargs)
  File "/home/ec2-user/environment/m1/app/core-service/core/engine.py", line 149, in get_next_task
    return self.db.get_next_task()
AttributeError: 'NoneType' object has no attribute 'get_next_task'

[2021-10-05 12:50:55] I engine | Traceback (most recent call last):
  File "/home/ec2-user/environment/m1/app/core-service/core/engine.py", line 127, in wrapper
    return function(self, *args, **kwargs)
  File "/home/ec2-user/environment/m1/app/core-service/core/engine.py", line 149, in get_next_task
    return self.db.get_next_task()
AttributeError: 'NoneType' object has no attribute 'get_next_task'

[2021-10-05 12:50:56] I engine | Traceback (most recent call last):
  File "/home/ec2-user/environment/m1/app/core-service/core/engine.py", line 127, in wrapper
    return function(self, *args, **kwargs)
  File "/home/ec2-user/environment/m1/app/core-service/core/engine.py", line 149, in get_next_task
    return self.db.get_next_task()
AttributeError: 'NoneType' object has no attribute 'get_next_task'

[2021-10-05 12:50:57] I engine | Traceback (most recent call last):
  File "/home/ec2-user/environment/m1/app/core-service/core/engine.py", line 127, in wrapper
    return function(self, *args, **kwargs)
  File "/home/ec2-user/environment/m1/app/core-service/core/engine.py", line 149, in get_next_task
    return self.db.get_next_task()
AttributeError: 'NoneType' object has no attribute 'get_next_task'

[2021-10-05 12:50:58] I engine | Traceback (most recent call last):
  File "/home/ec2-user/environment/m1/app/core-service/core/engine.py", line 127, in wrapper
    return function(self, *args, **kwargs)
  File "/home/ec2-user/environment/m1/app/core-service/core/engine.py", line 149, in get_next_task
    return self.db.get_next_task()
AttributeError: 'NoneType' object has no attribute 'get_next_task'

[2021-10-05 12:50:59] I engine | Traceback (most recent call last):
  File "/home/ec2-user/environment/m1/app/core-service/core/engine.py", line 127, in wrapper
    return function(self, *args, **kwargs)
  File "/home/ec2-user/environment/m1/app/core-service/core/engine.py", line 149, in get_next_task
    return self.db.get_next_task()
AttributeError: 'NoneType' object has no attribute 'get_next_task'

[2021-10-05 12:51:00] I engine | Traceback (most recent call last):
  File "/home/ec2-user/environment/m1/app/core-service/core/engine.py", line 127, in wrapper
    return function(self, *args, **kwargs)
  File "/home/ec2-user/environment/m1/app/core-service/core/engine.py", line 149, in get_next_task
    return self.db.get_next_task()
AttributeError: 'NoneType' object has no attribute 'get_next_task'

[2021-10-05 12:51:01] I engine | Traceback (most recent call last):
  File "/home/ec2-user/environment/m1/app/core-service/core/engine.py", line 127, in wrapper
    return function(self, *args, **kwargs)
  File "/home/ec2-user/environment/m1/app/core-service/core/engine.py", line 149, in get_next_task
    return self.db.get_next_task()
AttributeError: 'NoneType' object has no attribute 'get_next_task'

[2021-10-05 12:51:02] I engine | Traceback (most recent call last):
  File "/home/ec2-user/environment/m1/app/core-service/core/engine.py", line 127, in wrapper
    return function(self, *args, **kwargs)
  File "/home/ec2-user/environment/m1/app/core-service/core/engine.py", line 149, in get_next_task
    return self.db.get_next_task()
AttributeError: 'NoneType' object has no attribute 'get_next_task'

[2021-10-05 12:51:03] I engine | Traceback (most recent call last):
  File "/home/ec2-user/environment/m1/app/core-service/core/engine.py", line 127, in wrapper
    return function(self, *args, **kwargs)
  File "/home/ec2-user/environment/m1/app/core-service/core/engine.py", line 149, in get_next_task
    return self.db.get_next_task()
AttributeError: 'NoneType' object has no attribute 'get_next_task'

[2021-10-05 12:51:04] I engine | Traceback (most recent call last):
  File "/home/ec2-user/environment/m1/app/core-service/core/engine.py", line 127, in wrapper
    return function(self, *args, **kwargs)
  File "/home/ec2-user/environment/m1/app/core-service/core/engine.py", line 149, in get_next_task
    return self.db.get_next_task()
AttributeError: 'NoneType' object has no attribute 'get_next_task'

[2021-10-05 12:51:05] I engine | Traceback (most recent call last):
  File "/home/ec2-user/environment/m1/app/core-service/core/engine.py", line 127, in wrapper
    return function(self, *args, **kwargs)
  File "/home/ec2-user/environment/m1/app/core-service/core/engine.py", line 149, in get_next_task
    return self.db.get_next_task()
AttributeError: 'NoneType' object has no attribute 'get_next_task'

[2021-10-05 12:51:06] I engine | Traceback (most recent call last):
  File "/home/ec2-user/environment/m1/app/core-service/core/engine.py", line 127, in wrapper
    return function(self, *args, **kwargs)
  File "/home/ec2-user/environment/m1/app/core-service/core/engine.py", line 149, in get_next_task
    return self.db.get_next_task()
AttributeError: 'NoneType' object has no attribute 'get_next_task'

[2021-10-05 12:51:07] I engine | Traceback (most recent call last):
  File "/home/ec2-user/environment/m1/app/core-service/core/engine.py", line 127, in wrapper
    return function(self, *args, **kwargs)
  File "/home/ec2-user/environment/m1/app/core-service/core/engine.py", line 149, in get_next_task
    return self.db.get_next_task()
AttributeError: 'NoneType' object has no attribute 'get_next_task'

[2021-10-05 12:51:08] I engine | Traceback (most recent call last):
  File "/home/ec2-user/environment/m1/app/core-service/core/engine.py", line 127, in wrapper
    return function(self, *args, **kwargs)
  File "/home/ec2-user/environment/m1/app/core-service/core/engine.py", line 149, in get_next_task
    return self.db.get_next_task()
AttributeError: 'NoneType' object has no attribute 'get_next_task'

[2021-10-05 12:51:09] I engine | Traceback (most recent call last):
  File "/home/ec2-user/environment/m1/app/core-service/core/engine.py", line 127, in wrapper
    return function(self, *args, **kwargs)
  File "/home/ec2-user/environment/m1/app/core-service/core/engine.py", line 149, in get_next_task
    return self.db.get_next_task()
AttributeError: 'NoneType' object has no attribute 'get_next_task'

[2021-10-05 12:51:10] I engine | Traceback (most recent call last):
  File "/home/ec2-user/environment/m1/app/core-service/core/engine.py", line 127, in wrapper
    return function(self, *args, **kwargs)
  File "/home/ec2-user/environment/m1/app/core-service/core/engine.py", line 149, in get_next_task
    return self.db.get_next_task()
AttributeError: 'NoneType' object has no attribute 'get_next_task'

[2021-10-05 12:51:11] I engine | Traceback (most recent call last):
  File "/home/ec2-user/environment/m1/app/core-service/core/engine.py", line 127, in wrapper
    return function(self, *args, **kwargs)
  File "/home/ec2-user/environment/m1/app/core-service/core/engine.py", line 149, in get_next_task
    return self.db.get_next_task()
AttributeError: 'NoneType' object has no attribute 'get_next_task'

[2021-10-05 12:51:12] I engine | Traceback (most recent call last):
  File "/home/ec2-user/environment/m1/app/core-service/core/engine.py", line 127, in wrapper
    return function(self, *args, **kwargs)
  File "/home/ec2-user/environment/m1/app/core-service/core/engine.py", line 149, in get_next_task
    return self.db.get_next_task()
AttributeError: 'NoneType' object has no attribute 'get_next_task'

[2021-10-05 12:51:13] I engine | Traceback (most recent call last):
  File "/home/ec2-user/environment/m1/app/core-service/core/engine.py", line 127, in wrapper
    return function(self, *args, **kwargs)
  File "/home/ec2-user/environment/m1/app/core-service/core/engine.py", line 149, in get_next_task
    return self.db.get_next_task()
AttributeError: 'NoneType' object has no attribute 'get_next_task'

[2021-10-05 12:51:14] I engine | Traceback (most recent call last):
  File "/home/ec2-user/environment/m1/app/core-service/core/engine.py", line 127, in wrapper
    return function(self, *args, **kwargs)
  File "/home/ec2-user/environment/m1/app/core-service/core/engine.py", line 149, in get_next_task
    return self.db.get_next_task()
AttributeError: 'NoneType' object has no attribute 'get_next_task'

[2021-10-05 12:51:15] I engine | Traceback (most recent call last):
  File "/home/ec2-user/environment/m1/app/core-service/core/engine.py", line 127, in wrapper
    return function(self, *args, **kwargs)
  File "/home/ec2-user/environment/m1/app/core-service/core/engine.py", line 149, in get_next_task
    return self.db.get_next_task()
AttributeError: 'NoneType' object has no attribute 'get_next_task'

[2021-10-05 12:51:16] I engine | Traceback (most recent call last):
  File "/home/ec2-user/environment/m1/app/core-service/core/engine.py", line 127, in wrapper
    return function(self, *args, **kwargs)
  File "/home/ec2-user/environment/m1/app/core-service/core/engine.py", line 149, in get_next_task
    return self.db.get_next_task()
AttributeError: 'NoneType' object has no attribute 'get_next_task'

[2021-10-05 12:51:17] I engine | Traceback (most recent call last):
  File "/home/ec2-user/environment/m1/app/core-service/core/engine.py", line 127, in wrapper
    return function(self, *args, **kwargs)
  File "/home/ec2-user/environment/m1/app/core-service/core/engine.py", line 149, in get_next_task
    return self.db.get_next_task()
AttributeError: 'NoneType' object has no attribute 'get_next_task'

[2021-10-05 12:51:18] I engine | Traceback (most recent call last):
  File "/home/ec2-user/environment/m1/app/core-service/core/engine.py", line 127, in wrapper
    return function(self, *args, **kwargs)
  File "/home/ec2-user/environment/m1/app/core-service/core/engine.py", line 149, in get_next_task
    return self.db.get_next_task()
AttributeError: 'NoneType' object has no attribute 'get_next_task'

[2021-10-05 12:51:19] I engine | Traceback (most recent call last):
  File "/home/ec2-user/environment/m1/app/core-service/core/engine.py", line 127, in wrapper
    return function(self, *args, **kwargs)
  File "/home/ec2-user/environment/m1/app/core-service/core/engine.py", line 149, in get_next_task
    return self.db.get_next_task()
AttributeError: 'NoneType' object has no attribute 'get_next_task'

[2021-10-05 12:51:20] I engine | Traceback (most recent call last):
  File "/home/ec2-user/environment/m1/app/core-service/core/engine.py", line 127, in wrapper
    return function(self, *args, **kwargs)
  File "/home/ec2-user/environment/m1/app/core-service/core/engine.py", line 149, in get_next_task
    return self.db.get_next_task()
AttributeError: 'NoneType' object has no attribute 'get_next_task'

[2021-10-05 12:51:21] I engine | Traceback (most recent call last):
  File "/home/ec2-user/environment/m1/app/core-service/core/engine.py", line 127, in wrapper
    return function(self, *args, **kwargs)
  File "/home/ec2-user/environment/m1/app/core-service/core/engine.py", line 149, in get_next_task
    return self.db.get_next_task()
AttributeError: 'NoneType' object has no attribute 'get_next_task'

[2021-10-05 12:51:22] I engine | Traceback (most recent call last):
  File "/home/ec2-user/environment/m1/app/core-service/core/engine.py", line 127, in wrapper
    return function(self, *args, **kwargs)
  File "/home/ec2-user/environment/m1/app/core-service/core/engine.py", line 149, in get_next_task
    return self.db.get_next_task()
AttributeError: 'NoneType' object has no attribute 'get_next_task'

[2021-10-05 12:51:23] I engine | Traceback (most recent call last):
  File "/home/ec2-user/environment/m1/app/core-service/core/engine.py", line 127, in wrapper
    return function(self, *args, **kwargs)
  File "/home/ec2-user/environment/m1/app/core-service/core/engine.py", line 149, in get_next_task
    return self.db.get_next_task()
AttributeError: 'NoneType' object has no attribute 'get_next_task'

[2021-10-05 12:51:24] I engine | Traceback (most recent call last):
  File "/home/ec2-user/environment/m1/app/core-service/core/engine.py", line 127, in wrapper
    return function(self, *args, **kwargs)
  File "/home/ec2-user/environment/m1/app/core-service/core/engine.py", line 149, in get_next_task
    return self.db.get_next_task()
AttributeError: 'NoneType' object has no attribute 'get_next_task'

[2021-10-05 12:51:25] I engine | Traceback (most recent call last):
  File "/home/ec2-user/environment/m1/app/core-service/core/engine.py", line 127, in wrapper
    return function(self, *args, **kwargs)
  File "/home/ec2-user/environment/m1/app/core-service/core/engine.py", line 149, in get_next_task
    return self.db.get_next_task()
AttributeError: 'NoneType' object has no attribute 'get_next_task'

[2021-10-05 12:51:26] I engine | Traceback (most recent call last):
  File "/home/ec2-user/environment/m1/app/core-service/core/engine.py", line 127, in wrapper
    return function(self, *args, **kwargs)
  File "/home/ec2-user/environment/m1/app/core-service/core/engine.py", line 149, in get_next_task
    return self.db.get_next_task()
AttributeError: 'NoneType' object has no attribute 'get_next_task'

[2021-10-05 12:51:27] I engine | Traceback (most recent call last):
  File "/home/ec2-user/environment/m1/app/core-service/core/engine.py", line 127, in wrapper
    return function(self, *args, **kwargs)
  File "/home/ec2-user/environment/m1/app/core-service/core/engine.py", line 149, in get_next_task
    return self.db.get_next_task()
AttributeError: 'NoneType' object has no attribute 'get_next_task'

[2021-10-05 12:51:28] I engine | Traceback (most recent call last):
  File "/home/ec2-user/environment/m1/app/core-service/core/engine.py", line 127, in wrapper
    return function(self, *args, **kwargs)
  File "/home/ec2-user/environment/m1/app/core-service/core/engine.py", line 149, in get_next_task
    return self.db.get_next_task()
AttributeError: 'NoneType' object has no attribute 'get_next_task'

[2021-10-05 12:51:29] I engine | Traceback (most recent call last):
  File "/home/ec2-user/environment/m1/app/core-service/core/engine.py", line 127, in wrapper
    return function(self, *args, **kwargs)
  File "/home/ec2-user/environment/m1/app/core-service/core/engine.py", line 149, in get_next_task
    return self.db.get_next_task()
AttributeError: 'NoneType' object has no attribute 'get_next_task'

[2021-10-05 12:51:30] I engine | Traceback (most recent call last):
  File "/home/ec2-user/environment/m1/app/core-service/core/engine.py", line 127, in wrapper
    return function(self, *args, **kwargs)
  File "/home/ec2-user/environment/m1/app/core-service/core/engine.py", line 149, in get_next_task
    return self.db.get_next_task()
AttributeError: 'NoneType' object has no attribute 'get_next_task'

[2021-10-05 12:51:31] I engine | Traceback (most recent call last):
  File "/home/ec2-user/environment/m1/app/core-service/core/engine.py", line 127, in wrapper
    return function(self, *args, **kwargs)
  File "/home/ec2-user/environment/m1/app/core-service/core/engine.py", line 149, in get_next_task
    return self.db.get_next_task()
AttributeError: 'NoneType' object has no attribute 'get_next_task'

[2021-10-05 12:51:32] I engine | Traceback (most recent call last):
  File "/home/ec2-user/environment/m1/app/core-service/core/engine.py", line 127, in wrapper
    return function(self, *args, **kwargs)
  File "/home/ec2-user/environment/m1/app/core-service/core/engine.py", line 149, in get_next_task
    return self.db.get_next_task()
AttributeError: 'NoneType' object has no attribute 'get_next_task'

[2021-10-05 12:51:33] I engine | Traceback (most recent call last):
  File "/home/ec2-user/environment/m1/app/core-service/core/engine.py", line 127, in wrapper
    return function(self, *args, **kwargs)
  File "/home/ec2-user/environment/m1/app/core-service/core/engine.py", line 149, in get_next_task
    return self.db.get_next_task()
AttributeError: 'NoneType' object has no attribute 'get_next_task'

[2021-10-05 12:51:34] I engine | Traceback (most recent call last):
  File "/home/ec2-user/environment/m1/app/core-service/core/engine.py", line 127, in wrapper
    return function(self, *args, **kwargs)
  File "/home/ec2-user/environment/m1/app/core-service/core/engine.py", line 149, in get_next_task
    return self.db.get_next_task()
AttributeError: 'NoneType' object has no attribute 'get_next_task'

[2021-10-05 12:51:35] I engine | Traceback (most recent call last):
  File "/home/ec2-user/environment/m1/app/core-service/core/engine.py", line 127, in wrapper
    return function(self, *args, **kwargs)
  File "/home/ec2-user/environment/m1/app/core-service/core/engine.py", line 149, in get_next_task
    return self.db.get_next_task()
AttributeError: 'NoneType' object has no attribute 'get_next_task'

[2021-10-05 12:51:36] I engine | Traceback (most recent call last):
  File "/home/ec2-user/environment/m1/app/core-service/core/engine.py", line 127, in wrapper
    return function(self, *args, **kwargs)
  File "/home/ec2-user/environment/m1/app/core-service/core/engine.py", line 149, in get_next_task
    return self.db.get_next_task()
AttributeError: 'NoneType' object has no attribute 'get_next_task'

[2021-10-05 12:51:37] I engine | Traceback (most recent call last):
  File "/home/ec2-user/environment/m1/app/core-service/core/engine.py", line 127, in wrapper
    return function(self, *args, **kwargs)
  File "/home/ec2-user/environment/m1/app/core-service/core/engine.py", line 149, in get_next_task
    return self.db.get_next_task()
AttributeError: 'NoneType' object has no attribute 'get_next_task'

[2021-10-05 12:51:38] I engine | Traceback (most recent call last):
  File "/home/ec2-user/environment/m1/app/core-service/core/engine.py", line 127, in wrapper
    return function(self, *args, **kwargs)
  File "/home/ec2-user/environment/m1/app/core-service/core/engine.py", line 149, in get_next_task
    return self.db.get_next_task()
AttributeError: 'NoneType' object has no attribute 'get_next_task'

[2021-10-05 12:51:39] I engine | Traceback (most recent call last):
  File "/home/ec2-user/environment/m1/app/core-service/core/engine.py", line 127, in wrapper
    return function(self, *args, **kwargs)
  File "/home/ec2-user/environment/m1/app/core-service/core/engine.py", line 149, in get_next_task
    return self.db.get_next_task()
AttributeError: 'NoneType' object has no attribute 'get_next_task'

[2021-10-05 12:51:40] I engine | Traceback (most recent call last):
  File "/home/ec2-user/environment/m1/app/core-service/core/engine.py", line 127, in wrapper
    return function(self, *args, **kwargs)
  File "/home/ec2-user/environment/m1/app/core-service/core/engine.py", line 149, in get_next_task
    return self.db.get_next_task()
AttributeError: 'NoneType' object has no attribute 'get_next_task'

[2021-10-05 12:51:41] I engine | Traceback (most recent call last):
  File "/home/ec2-user/environment/m1/app/core-service/core/engine.py", line 127, in wrapper
    return function(self, *args, **kwargs)
  File "/home/ec2-user/environment/m1/app/core-service/core/engine.py", line 149, in get_next_task
    return self.db.get_next_task()
AttributeError: 'NoneType' object has no attribute 'get_next_task'

[2021-10-05 12:51:42] I engine | Traceback (most recent call last):
  File "/home/ec2-user/environment/m1/app/core-service/core/engine.py", line 127, in wrapper
    return function(self, *args, **kwargs)
  File "/home/ec2-user/environment/m1/app/core-service/core/engine.py", line 149, in get_next_task
    return self.db.get_next_task()
AttributeError: 'NoneType' object has no attribute 'get_next_task'

[2021-10-05 12:51:43] I engine | Traceback (most recent call last):
  File "/home/ec2-user/environment/m1/app/core-service/core/engine.py", line 127, in wrapper
    return function(self, *args, **kwargs)
  File "/home/ec2-user/environment/m1/app/core-service/core/engine.py", line 149, in get_next_task
    return self.db.get_next_task()
AttributeError: 'NoneType' object has no attribute 'get_next_task'

